Workbook

Sheet How to Use
B1: The Capability Gap Assessment
B2: From AI Will Scale Good Leadership and Bad Leadership: The CHRO’s Method for Redesigning Work Before AI Scales What’s Broken, by Liz Corey | Toolbox No. 8 | OnTheGrow Leadership
B3: © 2026 Elizabeth A. Corey. All rights reserved. GROWTH Execution Model™. onthegrow.ai
B5: AI readiness has two parts, and organizations routinely test only the first. Literacy is whether a person can explain the five terms. Capability is what they actually do when it counts. The gap between knowing and doing is where the risk lives. This workbook measures both and tells you which of the six skills to rehearse next.
B7: HOW THIS WORKBOOK IS SET UP
B8: Literacy Quiz | C8: Ten questions on the five terms and their business consequences. The cheap half, and the smaller one.
B9: Scenarios | C9: Three scenarios with real artifacts. Capability is scored on behavior, not vocabulary.
B10: Six Skills Scale | C10: The six skills that close the gap, each with observable anchors at three levels. Score people against it during the scenarios.
B11: Team Map | C11: One row per person. Enter quiz answers and six skill ratings. The workbook plots the quadrant and names the plan.
B12: Example rows | C12: A recruiting team of eight is filled in so you can see a finished map. Replace them with your own people.
B13: Yellow cells | C13: Type in the yellow cells only. Every other cell is a formula.
B15: HOW TO RUN IT
B16: 1. Measure literacy the cheap way | C16: Give the ten-question quiz. Enter each person’s answers on the Team Map. Eight or more is high literacy.
B17: 2. Measure capability the real way | C17: Run the three scenarios in small groups with real artifacts and an immediate debrief. Rate each of the six skills 1 to 3 on the scale. Say nothing about the fabrication in advance.
B18: 3. Plot the four profiles and plan by quadrant | C18: Operators teach. Naturals get vocabulary. Honest beginners get the full sequence. Confident beginners get scenarios first and autonomy last, whatever their confidence says.
B19: 4. Reassess after rehearsal cycles | C19: Not calendar quarters. Capability moves when practiced, and the map should move with it.
B21: THE CHRO’S MOVE
B22: Run it on your own team first | C22: Three scenarios, one hour, your HR leadership group. Score behaviors. The results will humble the room, which is the point: you cannot credibly assess a gap you have not measured in yourself. Then take the method to one business unit, managers first, and let the completion-certificate budget pay for the scenarios.
B24: WANT IT DONE FASTER?
B25: Capability Scenario Scorer | C25: The AI-powered version runs the scenarios with each person, scores the behaviors against the six skills, and builds the team map. Early access. Call for pricing. Book a conversation at onthegrow.ai
B26: Six Skills Interview Agent | C26: Interviews candidates and employees against the Six Skills Behavioral Scale. Available now. Call for pricing.
B28: © 2026 Elizabeth A. Corey. All rights reserved. GROWTH Execution Model™. onthegrow.ai

Sheet Literacy Quiz
A1: Literacy Quiz: The Five Terms and Their Consequences
A2: HOW TO USE THIS TAB: Give these ten questions on paper or on screen. One best answer each. Record each person’s answers (A, B, C, or D) on the Team Map. The key is on the Answer Key tab, which you can hide before you hand this out.
A3: © 2026 Elizabeth A. Corey. All rights reserved. GROWTH Execution Model™. onthegrow.ai
A5: # | B5: Term | C5: Question | D5: A | E5: B | F5: C | G5: D
A6: 1 | B6: The prediction engine | C6: A model gives a fluent, specific answer about your company’s PTO policy. What is the safest assumption? | D6: It predicted a plausible answer. It has never read your policy unless it was grounded in it. | E6: It looked the policy up. | F6: It knows the policy from training. | G6: It is right because it sounded specific.
A7: 2 | B7: The prediction engine | C7: Which statement is true of a large language model on its own? | D7: It predicts the next words from patterns. | E7: It stores your documents. | F7: It checks facts before answering. | G7: It knows what it does not know.
A8: 3 | B8: The assignment | C8: A manager gets a generic, useless summary from AI. Where does the fix usually belong? | D8: In the request: add goal, context, constraints, output. | E8: In a better model. | F8: In editing the summary by hand. | G8: In asking the same request again.
A9: 4 | B9: The assignment | C9: Which of these is the complete assignment structure from the book? | D9: Goal, Context, Constraints, Output. | E9: Prompt, Model, Answer. | F9: Who, What, When. | G9: Input, Process, Output.
A10: 5 | B10: The confident fabrication | C10: An AI-drafted letter cites a policy section you do not recognize. What does fluency tell you about whether it is real? | D10: Nothing. Fluent never means factual. | E10: It is probably real if it sounds specific. | F10: It is real if the model is a recent version. | G10: It is real if nobody else questioned it.
A11: 6 | B11: The confident fabrication | C11: Which number should set how much checking an AI output gets? | D11: The cost of being wrong and the cost of checking it. | E11: How long the output is. | F11: How confident the model sounded. | G11: How senior the person who asked is.
A12: 7 | B12: The grounding | C12: Grounding AI in your handbook means it answers from your handbook. What else does it mean? | D12: It inherits the handbook exactly as it stands, outdated parts included. | E12: The handbook is now correct. | F12: Employees no longer need the handbook. | G12: The AI will fix contradictions it finds.
A13: 8 | B13: The grounding | C13: Two policy documents disagree and both are in the grounded set. What does the system do? | D13: It picks one. It does not adjudicate. | E13: It flags the conflict every time. | F13: It averages the two. | G13: It refuses to answer.
A14: 9 | B14: The delegated worker | C14: What changes the moment software pursues an outcome with delegated authority? | D14: Workforce rules apply: a job description, decision boundaries, a named human owner. | E14: IT owns it. | F14: Nothing, it is still a tool. | G14: The vendor is accountable.
A15: 10 | B15: The delegated worker | C15: An agent produces fluent output in a situation it was never meant to handle. What was missing? | D15: An escalation path and defined decision rights. | E15: A faster model. | F15: A longer prompt. | G15: A bigger team.
A17: Scoring: one point per correct answer. 8 to 10 is high literacy. This is necessary, measurable, and not remotely sufficient. The scenarios are the test that counts.

Sheet Answer Key
A1: 1 | B1: A
A2: 2 | B2: A
A3: 3 | B3: A
A4: 4 | B4: A
A5: 5 | B5: A
A6: 6 | B6: A
A7: 7 | B7: A
A8: 8 | B8: A
A9: 9 | B9: A
A10: 10 | B10: A

Sheet Scenarios
A1: Three Scenarios: Capability Is Behavior Under Conditions
A2: HOW TO USE THIS TAB: Small groups, real artifacts from your own company, immediate debrief. One hour covers all three. Score each person on the Six Skills Scale while you watch. Behavior, not vocabulary.
A3: © 2026 Elizabeth A. Corey. All rights reserved. GROWTH Execution Model™. onthegrow.ai
A5: Scenario | B5: The artifact and the setup | C5: What to watch | D5: Skills it reveals
A6: 1. The fabricated citation | B6: An AI-drafted policy answer (or termination letter) that cites a policy section that does not exist, handed over under deadline pressure. Say nothing about the fabrication in advance. | C6: Did they verify the citation, or admire the prose? How quickly? Did they name what had to be true for the document to be safe? | D6: Output interrogation, Verification judgment, Inquiry
A7: 2. The ambiguous escalation | B7: A flagged agent escalation that arrives ambiguous: a benefits question routed to a person with a low-confidence note and no clear reason. | C7: Did they escalate, investigate, or shrug? Did they ask what the agent was missing? Did they treat the pattern as a knowledge problem before an agent problem? | D7: Inquiry, Coaching, Verification judgment
A8: 3. The weak first draft | B8: A real delegation: they brief AI on a task, and the first output is mediocre on purpose. | C8: Did they fix the output or fix the assignment? Was the rewritten brief complete (goal, context, constraints, output)? Did they say what the freed time becomes? | D8: Delegation, Coaching, Reinvestment discipline
A10: Keep it running. The cheapest rehearsal is a weekly thirty-minute after-action review: somebody brings a real case, the brief they wrote, what came back, what was good, what was wrong, and what they did about it.

Sheet Six Skills Scale
A1: The Six Skills Behavioral Scale
A2: HOW TO USE THIS TAB: Rate each person 1, 2, or 3 on each skill, from what you saw in the scenarios. Every anchor is observable. A brief is either complete or it is not. A citation was either checked or it was not.
A3: © 2026 Elizabeth A. Corey. All rights reserved. GROWTH Execution Model™. onthegrow.ai
A5: Skill | B5: What it is | C5: 1 Beginner | D5: 2 Developing | E5: 3 Operator
A6: Delegation | B6: Writing the complete assignment (goal, context, constraints, output) and recognizing when a weak result traces to a weak brief. | C6: Types a one-line request and takes what comes back. Fixes weak output by hand. | D6: Writes goal and output. Context and constraints are thin. Sometimes traces a weak result to the brief. | E6: Writes all four parts without prompting. When output is weak, rewrites the assignment, not the output.
A7: Inquiry | B7: Knowing how to ask the next question. Not accepting the first answer, even when it sounds good. | C7: Accepts the first answer. Asks nothing further. | D7: Asks one follow-up when something looks off. | E7: Stays in the question: what is missing, what changed, what assumption is hiding, what have I not thought to ask.
A8: Output interrogation | B8: Treating fluency as a claim, not a credential. Asking what in this document must be true for it to be safe, and checking exactly those things. | C8: Proofreads for tone and typos. Forwards the fabricated citation. | D8: Spot-checks a fact or two. Catches an error when it looks wrong. | E8: Names what must be true for the output to be safe, checks exactly those things, and catches the fabrication.
A9: Verification judgment | B9: Knowing how much scrutiny this output deserves: wrongness cost and verification cost applied at the desk level. | C9: Scrutinizes everything or nothing. Drowns or detonates. | D9: Adjusts scrutiny when reminded of the stakes. | E9: Scrutiny matches the cost of being wrong. The recap gets a skim. The compliance answer gets the full treatment.
A10: Coaching | B10: Naming good output so it repeats. Tracing poor output to its cause (the brief, the context, the standard) and correcting there. Still coaching the person, not handing them an AI answer. | C10: Patches poor output by hand. Hands people AI answers and calls it development. | D10: Names good output. Traces some poor output to the brief. | E10: Corrects at the cause every time, for the agent and the person. Examines thinking, tests assumptions, improves the next attempt.
A11: Reinvestment discipline | B11: The personal habit of deciding what freed capacity should become, before volume fills it. | C11: Freed hours fill with more of the same. | D11: Can name where some freed time went. | E11: Decides in advance what the capacity becomes, and can show it.
A12: Notice what the list is: delegate, inquire, interrogate, verify, coach, reinvest. These are management skills in the order of a manager’s day. There is no separate discipline called working with AI. The only thing new is the worker.

Sheet Team Map
A1: Team Map: Who Is Where on the Knowing-Doing Map
A2: HOW TO USE THIS TAB: One row per person. Type the ten quiz answers as letters and the six skill ratings as 1, 2, or 3, all in the yellow cells. The workbook scores literacy, averages capability, names the quadrant, and writes the plan. The recruiting rows are an example; replace them.
A3: © 2026 Elizabeth A. Corey. All rights reserved. GROWTH Execution Model™. onthegrow.ai
A4: Person | B4: Role | C4: Q1 | D4: Q2 | E4: Q3 | F4: Q4 | G4: Q5 | H4: Q6 | I4: Q7 | J4: Q8 | K4: Q9 | L4: Q10 | M4: Literacy (of 10) | N4: Delegation | O4: Inquiry | P4: Output interrogation | Q4: Verification judgment | R4: Coaching | S4: Reinvestment discipline | T4: Capability (avg) | U4: Weakest skill | V4: Quadrant | W4: The plan | X4: Autonomy | Y4: Notes
A5: Recruiting manager | B5: Manager | C5: A | D5: A | E5: A | F5: A | G5: A | H5: A | I5: A | J5: A | K5: A | L5: A | M5: =IF(A5="","",IF(COUNTA(C5:L5)<10,"",IF(UPPER(TRIM(C5))='Answer Key'!$B$1,1,0)+IF(UPPER(TRIM(D5))='Answer Key'!$B$2,1,0)+IF(UPPER(TRIM(E5))='Answer Key'!$B$3,1,0)+IF(UPPER(TRIM(F5))='Answer Key'!$B$4,1,0)+IF(UPPER(TRIM(G5))='Answer Key'!$B$5,1,0)+IF(UPPER(TRIM(H5))='Answer Key'!$B$6,1,0)+IF(UPPER(TRIM(I5))='Answer Key'!$B$7,1,0)+IF(UPPER(TRIM(J5))='Answer Key'!$B$8,1,0)+IF(UPPER(TRIM(K5))='Answer Key'!$B$9,1,0)+IF(UPPER(TRIM(L5))='Answer Key'!$B$10,1,0))) | N5: 3 | O5: 3 | P5: 3 | Q5: 3 | R5: 2 | S5: 3 | T5: =IF(A5="","",IF(COUNT(N5:S5)<6,"",ROUND(AVERAGE(N5:S5),1))) | U5: =IF(T5="","",INDEX($N$4:$S$4,MATCH(MIN(N5:S5),N5:S5,0))) | V5: =IF(OR(M5="",T5=""),"",IF(M5>=8,IF(T5>=2.5,"Operator","Confident beginner"),IF(T5>=2.5,"Natural","Honest beginner"))) | W5: =IF(V5="","",IF(V5="Operator","Teach. Run the after-action review.",IF(V5="Natural","Vocabulary only. Judgment already transfers.",IF(V5="Honest beginner","The full sequence: terms, then scenarios, then rehearsal.","Scenarios first, autonomy last, whatever their confidence says.")))) | X5: =IF(V5="","",IF(T5>=2.5,"Grant on evidence",IF(T5>=2,"Supervised","Hold"))) | Z5: Should run the next after-action review.
A6: Senior recruiter | B6: Individual contributor | C6: A | D6: B | E6: A | F6: A | G6: A | H6: A | I6: A | J6: A | K6: A | L6: B | M6: =IF(A6="","",IF(COUNTA(C6:L6)<10,"",IF(UPPER(TRIM(C6))='Answer Key'!$B$1,1,0)+IF(UPPER(TRIM(D6))='Answer Key'!$B$2,1,0)+IF(UPPER(TRIM(E6))='Answer Key'!$B$3,1,0)+IF(UPPER(TRIM(F6))='Answer Key'!$B$4,1,0)+IF(UPPER(TRIM(G6))='Answer Key'!$B$5,1,0)+IF(UPPER(TRIM(H6))='Answer Key'!$B$6,1,0)+IF(UPPER(TRIM(I6))='Answer Key'!$B$7,1,0)+IF(UPPER(TRIM(J6))='Answer Key'!$B$8,1,0)+IF(UPPER(TRIM(K6))='Answer Key'!$B$9,1,0)+IF(UPPER(TRIM(L6))='Answer Key'!$B$10,1,0))) | N6: 3 | O6: 3 | P6: 2 | Q6: 3 | R6: 2 | S6: 2 | T6: =IF(A6="","",IF(COUNT(N6:S6)<6,"",ROUND(AVERAGE(N6:S6),1))) | U6: =IF(T6="","",INDEX($N$4:$S$4,MATCH(MIN(N6:S6),N6:S6,0))) | V6: =IF(OR(M6="",T6=""),"",IF(M6>=8,IF(T6>=2.5,"Operator","Confident beginner"),IF(T6>=2.5,"Natural","Honest beginner"))) | W6: =IF(V6="","",IF(V6="Operator","Teach. Run the after-action review.",IF(V6="Natural","Vocabulary only. Judgment already transfers.",IF(V6="Honest beginner","The full sequence: terms, then scenarios, then rehearsal.","Scenarios first, autonomy last, whatever their confidence says.")))) | X6: =IF(V6="","",IF(T6>=2.5,"Grant on evidence",IF(T6>=2,"Supervised","Hold")))
A7: Recruiter | B7: Individual contributor | C7: A | D7: A | E7: A | F7: A | G7: A | H7: A | I7: A | J7: A | K7: B | L7: A | M7: =IF(A7="","",IF(COUNTA(C7:L7)<10,"",IF(UPPER(TRIM(C7))='Answer Key'!$B$1,1,0)+IF(UPPER(TRIM(D7))='Answer Key'!$B$2,1,0)+IF(UPPER(TRIM(E7))='Answer Key'!$B$3,1,0)+IF(UPPER(TRIM(F7))='Answer Key'!$B$4,1,0)+IF(UPPER(TRIM(G7))='Answer Key'!$B$5,1,0)+IF(UPPER(TRIM(H7))='Answer Key'!$B$6,1,0)+IF(UPPER(TRIM(I7))='Answer Key'!$B$7,1,0)+IF(UPPER(TRIM(J7))='Answer Key'!$B$8,1,0)+IF(UPPER(TRIM(K7))='Answer Key'!$B$9,1,0)+IF(UPPER(TRIM(L7))='Answer Key'!$B$10,1,0))) | N7: 1 | O7: 1 | P7: 1 | Q7: 1 | R7: 1 | S7: 1 | T7: =IF(A7="","",IF(COUNT(N7:S7)<6,"",ROUND(AVERAGE(N7:S7),1))) | U7: =IF(T7="","",INDEX($N$4:$S$4,MATCH(MIN(N7:S7),N7:S7,0))) | V7: =IF(OR(M7="",T7=""),"",IF(M7>=8,IF(T7>=2.5,"Operator","Confident beginner"),IF(T7>=2.5,"Natural","Honest beginner"))) | W7: =IF(V7="","",IF(V7="Operator","Teach. Run the after-action review.",IF(V7="Natural","Vocabulary only. Judgment already transfers.",IF(V7="Honest beginner","The full sequence: terms, then scenarios, then rehearsal.","Scenarios first, autonomy last, whatever their confidence says.")))) | X7: =IF(V7="","",IF(T7>=2.5,"Grant on evidence",IF(T7>=2,"Supervised","Hold"))) | Z7: Scored 9 on the quiz and forwarded the fabricated citation without reading it.
A8: Recruiter | B8: Individual contributor | C8: A | D8: C | E8: B | F8: A | G8: B | H8: A | I8: A | J8: A | K8: A | L8: C | M8: =IF(A8="","",IF(COUNTA(C8:L8)<10,"",IF(UPPER(TRIM(C8))='Answer Key'!$B$1,1,0)+IF(UPPER(TRIM(D8))='Answer Key'!$B$2,1,0)+IF(UPPER(TRIM(E8))='Answer Key'!$B$3,1,0)+IF(UPPER(TRIM(F8))='Answer Key'!$B$4,1,0)+IF(UPPER(TRIM(G8))='Answer Key'!$B$5,1,0)+IF(UPPER(TRIM(H8))='Answer Key'!$B$6,1,0)+IF(UPPER(TRIM(I8))='Answer Key'!$B$7,1,0)+IF(UPPER(TRIM(J8))='Answer Key'!$B$8,1,0)+IF(UPPER(TRIM(K8))='Answer Key'!$B$9,1,0)+IF(UPPER(TRIM(L8))='Answer Key'!$B$10,1,0))) | N8: 3 | O8: 3 | P8: 3 | Q8: 3 | R8: 2 | S8: 2 | T8: =IF(A8="","",IF(COUNT(N8:S8)<6,"",ROUND(AVERAGE(N8:S8),1))) | U8: =IF(T8="","",INDEX($N$4:$S$4,MATCH(MIN(N8:S8),N8:S8,0))) | V8: =IF(OR(M8="",T8=""),"",IF(M8>=8,IF(T8>=2.5,"Operator","Confident beginner"),IF(T8>=2.5,"Natural","Honest beginner"))) | W8: =IF(V8="","",IF(V8="Operator","Teach. Run the after-action review.",IF(V8="Natural","Vocabulary only. Judgment already transfers.",IF(V8="Honest beginner","The full sequence: terms, then scenarios, then rehearsal.","Scenarios first, autonomy last, whatever their confidence says.")))) | X8: =IF(V8="","",IF(T8>=2.5,"Grant on evidence",IF(T8>=2,"Supervised","Hold"))) | Z8: Caught the fabrication in under a minute. Could not define grounding.
A9: Recruiting coordinator | B9: Individual contributor | C9: B | D9: C | E9: B | F9: B | G9: C | H9: B | I9: A | J9: A | K9: B | L9: C | M9: =IF(A9="","",IF(COUNTA(C9:L9)<10,"",IF(UPPER(TRIM(C9))='Answer Key'!$B$1,1,0)+IF(UPPER(TRIM(D9))='Answer Key'!$B$2,1,0)+IF(UPPER(TRIM(E9))='Answer Key'!$B$3,1,0)+IF(UPPER(TRIM(F9))='Answer Key'!$B$4,1,0)+IF(UPPER(TRIM(G9))='Answer Key'!$B$5,1,0)+IF(UPPER(TRIM(H9))='Answer Key'!$B$6,1,0)+IF(UPPER(TRIM(I9))='Answer Key'!$B$7,1,0)+IF(UPPER(TRIM(J9))='Answer Key'!$B$8,1,0)+IF(UPPER(TRIM(K9))='Answer Key'!$B$9,1,0)+IF(UPPER(TRIM(L9))='Answer Key'!$B$10,1,0))) | N9: 1 | O9: 2 | P9: 1 | Q9: 1 | R9: 1 | S9: 1 | T9: =IF(A9="","",IF(COUNT(N9:S9)<6,"",ROUND(AVERAGE(N9:S9),1))) | U9: =IF(T9="","",INDEX($N$4:$S$4,MATCH(MIN(N9:S9),N9:S9,0))) | V9: =IF(OR(M9="",T9=""),"",IF(M9>=8,IF(T9>=2.5,"Operator","Confident beginner"),IF(T9>=2.5,"Natural","Honest beginner"))) | W9: =IF(V9="","",IF(V9="Operator","Teach. Run the after-action review.",IF(V9="Natural","Vocabulary only. Judgment already transfers.",IF(V9="Honest beginner","The full sequence: terms, then scenarios, then rehearsal.","Scenarios first, autonomy last, whatever their confidence says.")))) | X9: =IF(V9="","",IF(T9>=2.5,"Grant on evidence",IF(T9>=2,"Supervised","Hold"))) | Z9: Asked for the five terms by name. Honest about the gap.
A10: Sourcer | B10: Individual contributor | C10: A | D10: A | E10: A | F10: B | G10: A | H10: A | I10: A | J10: A | K10: A | L10: A | M10: =IF(A10="","",IF(COUNTA(C10:L10)<10,"",IF(UPPER(TRIM(C10))='Answer Key'!$B$1,1,0)+IF(UPPER(TRIM(D10))='Answer Key'!$B$2,1,0)+IF(UPPER(TRIM(E10))='Answer Key'!$B$3,1,0)+IF(UPPER(TRIM(F10))='Answer Key'!$B$4,1,0)+IF(UPPER(TRIM(G10))='Answer Key'!$B$5,1,0)+IF(UPPER(TRIM(H10))='Answer Key'!$B$6,1,0)+IF(UPPER(TRIM(I10))='Answer Key'!$B$7,1,0)+IF(UPPER(TRIM(J10))='Answer Key'!$B$8,1,0)+IF(UPPER(TRIM(K10))='Answer Key'!$B$9,1,0)+IF(UPPER(TRIM(L10))='Answer Key'!$B$10,1,0))) | N10: 2 | O10: 1 | P10: 1 | Q10: 2 | R10: 1 | S10: 1 | T10: =IF(A10="","",IF(COUNT(N10:S10)<6,"",ROUND(AVERAGE(N10:S10),1))) | U10: =IF(T10="","",INDEX($N$4:$S$4,MATCH(MIN(N10:S10),N10:S10,0))) | V10: =IF(OR(M10="",T10=""),"",IF(M10>=8,IF(T10>=2.5,"Operator","Confident beginner"),IF(T10>=2.5,"Natural","Honest beginner"))) | W10: =IF(V10="","",IF(V10="Operator","Teach. Run the after-action review.",IF(V10="Natural","Vocabulary only. Judgment already transfers.",IF(V10="Honest beginner","The full sequence: terms, then scenarios, then rehearsal.","Scenarios first, autonomy last, whatever their confidence says.")))) | X10: =IF(V10="","",IF(T10>=2.5,"Grant on evidence",IF(T10>=2,"Supervised","Hold"))) | Z10: Admired the prose. Did not check the citation.
A11: Recruiting coordinator | B11: Individual contributor | C11: B | D11: B | E11: A | F11: B | G11: B | H11: C | I11: A | J11: B | K11: A | L11: C | M11: =IF(A11="","",IF(COUNTA(C11:L11)<10,"",IF(UPPER(TRIM(C11))='Answer Key'!$B$1,1,0)+IF(UPPER(TRIM(D11))='Answer Key'!$B$2,1,0)+IF(UPPER(TRIM(E11))='Answer Key'!$B$3,1,0)+IF(UPPER(TRIM(F11))='Answer Key'!$B$4,1,0)+IF(UPPER(TRIM(G11))='Answer Key'!$B$5,1,0)+IF(UPPER(TRIM(H11))='Answer Key'!$B$6,1,0)+IF(UPPER(TRIM(I11))='Answer Key'!$B$7,1,0)+IF(UPPER(TRIM(J11))='Answer Key'!$B$8,1,0)+IF(UPPER(TRIM(K11))='Answer Key'!$B$9,1,0)+IF(UPPER(TRIM(L11))='Answer Key'!$B$10,1,0))) | N11: 2 | O11: 3 | P11: 3 | Q11: 3 | R11: 2 | S11: 1 | T11: =IF(A11="","",IF(COUNT(N11:S11)<6,"",ROUND(AVERAGE(N11:S11),1))) | U11: =IF(T11="","",INDEX($N$4:$S$4,MATCH(MIN(N11:S11),N11:S11,0))) | V11: =IF(OR(M11="",T11=""),"",IF(M11>=8,IF(T11>=2.5,"Operator","Confident beginner"),IF(T11>=2.5,"Natural","Honest beginner"))) | W11: =IF(V11="","",IF(V11="Operator","Teach. Run the after-action review.",IF(V11="Natural","Vocabulary only. Judgment already transfers.",IF(V11="Honest beginner","The full sequence: terms, then scenarios, then rehearsal.","Scenarios first, autonomy last, whatever their confidence says.")))) | X11: =IF(V11="","",IF(T11>=2.5,"Grant on evidence",IF(T11>=2,"Supervised","Hold")))
A12: HR business partner | B12: Manager | C12: A | D12: A | E12: A | F12: A | G12: A | H12: A | I12: A | J12: B | K12: A | L12: A | M12: =IF(A12="","",IF(COUNTA(C12:L12)<10,"",IF(UPPER(TRIM(C12))='Answer Key'!$B$1,1,0)+IF(UPPER(TRIM(D12))='Answer Key'!$B$2,1,0)+IF(UPPER(TRIM(E12))='Answer Key'!$B$3,1,0)+IF(UPPER(TRIM(F12))='Answer Key'!$B$4,1,0)+IF(UPPER(TRIM(G12))='Answer Key'!$B$5,1,0)+IF(UPPER(TRIM(H12))='Answer Key'!$B$6,1,0)+IF(UPPER(TRIM(I12))='Answer Key'!$B$7,1,0)+IF(UPPER(TRIM(J12))='Answer Key'!$B$8,1,0)+IF(UPPER(TRIM(K12))='Answer Key'!$B$9,1,0)+IF(UPPER(TRIM(L12))='Answer Key'!$B$10,1,0))) | N12: 2 | O12: 2 | P12: 2 | Q12: 2 | R12: 3 | S12: 2 | T12: =IF(A12="","",IF(COUNT(N12:S12)<6,"",ROUND(AVERAGE(N12:S12),1))) | U12: =IF(T12="","",INDEX($N$4:$S$4,MATCH(MIN(N12:S12),N12:S12,0))) | V12: =IF(OR(M12="",T12=""),"",IF(M12>=8,IF(T12>=2.5,"Operator","Confident beginner"),IF(T12>=2.5,"Natural","Honest beginner"))) | W12: =IF(V12="","",IF(V12="Operator","Teach. Run the after-action review.",IF(V12="Natural","Vocabulary only. Judgment already transfers.",IF(V12="Honest beginner","The full sequence: terms, then scenarios, then rehearsal.","Scenarios first, autonomy last, whatever their confidence says.")))) | X12: =IF(V12="","",IF(T12>=2.5,"Grant on evidence",IF(T12>=2,"Supervised","Hold"))) | Z12: Good coach. Over-checks low-stakes output.
M13: =IF(A13="","",IF(COUNTA(C13:L13)<10,"",IF(UPPER(TRIM(C13))='Answer Key'!$B$1,1,0)+IF(UPPER(TRIM(D13))='Answer Key'!$B$2,1,0)+IF(UPPER(TRIM(E13))='Answer Key'!$B$3,1,0)+IF(UPPER(TRIM(F13))='Answer Key'!$B$4,1,0)+IF(UPPER(TRIM(G13))='Answer Key'!$B$5,1,0)+IF(UPPER(TRIM(H13))='Answer Key'!$B$6,1,0)+IF(UPPER(TRIM(I13))='Answer Key'!$B$7,1,0)+IF(UPPER(TRIM(J13))='Answer Key'!$B$8,1,0)+IF(UPPER(TRIM(K13))='Answer Key'!$B$9,1,0)+IF(UPPER(TRIM(L13))='Answer Key'!$B$10,1,0))) | T13: =IF(A13="","",IF(COUNT(N13:S13)<6,"",ROUND(AVERAGE(N13:S13),1))) | U13: =IF(T13="","",INDEX($N$4:$S$4,MATCH(MIN(N13:S13),N13:S13,0))) | V13: =IF(OR(M13="",T13=""),"",IF(M13>=8,IF(T13>=2.5,"Operator","Confident beginner"),IF(T13>=2.5,"Natural","Honest beginner"))) | W13: =IF(V13="","",IF(V13="Operator","Teach. Run the after-action review.",IF(V13="Natural","Vocabulary only. Judgment already transfers.",IF(V13="Honest beginner","The full sequence: terms, then scenarios, then rehearsal.","Scenarios first, autonomy last, whatever their confidence says.")))) | X13: =IF(V13="","",IF(T13>=2.5,"Grant on evidence",IF(T13>=2,"Supervised","Hold")))
M14: =IF(A14="","",IF(COUNTA(C14:L14)<10,"",IF(UPPER(TRIM(C14))='Answer Key'!$B$1,1,0)+IF(UPPER(TRIM(D14))='Answer Key'!$B$2,1,0)+IF(UPPER(TRIM(E14))='Answer Key'!$B$3,1,0)+IF(UPPER(TRIM(F14))='Answer Key'!$B$4,1,0)+IF(UPPER(TRIM(G14))='Answer Key'!$B$5,1,0)+IF(UPPER(TRIM(H14))='Answer Key'!$B$6,1,0)+IF(UPPER(TRIM(I14))='Answer Key'!$B$7,1,0)+IF(UPPER(TRIM(J14))='Answer Key'!$B$8,1,0)+IF(UPPER(TRIM(K14))='Answer Key'!$B$9,1,0)+IF(UPPER(TRIM(L14))='Answer Key'!$B$10,1,0))) | T14: =IF(A14="","",IF(COUNT(N14:S14)<6,"",ROUND(AVERAGE(N14:S14),1))) | U14: =IF(T14="","",INDEX($N$4:$S$4,MATCH(MIN(N14:S14),N14:S14,0))) | V14: =IF(OR(M14="",T14=""),"",IF(M14>=8,IF(T14>=2.5,"Operator","Confident beginner"),IF(T14>=2.5,"Natural","Honest beginner"))) | W14: =IF(V14="","",IF(V14="Operator","Teach. Run the after-action review.",IF(V14="Natural","Vocabulary only. Judgment already transfers.",IF(V14="Honest beginner","The full sequence: terms, then scenarios, then rehearsal.","Scenarios first, autonomy last, whatever their confidence says.")))) | X14: =IF(V14="","",IF(T14>=2.5,"Grant on evidence",IF(T14>=2,"Supervised","Hold")))
M15: =IF(A15="","",IF(COUNTA(C15:L15)<10,"",IF(UPPER(TRIM(C15))='Answer Key'!$B$1,1,0)+IF(UPPER(TRIM(D15))='Answer Key'!$B$2,1,0)+IF(UPPER(TRIM(E15))='Answer Key'!$B$3,1,0)+IF(UPPER(TRIM(F15))='Answer Key'!$B$4,1,0)+IF(UPPER(TRIM(G15))='Answer Key'!$B$5,1,0)+IF(UPPER(TRIM(H15))='Answer Key'!$B$6,1,0)+IF(UPPER(TRIM(I15))='Answer Key'!$B$7,1,0)+IF(UPPER(TRIM(J15))='Answer Key'!$B$8,1,0)+IF(UPPER(TRIM(K15))='Answer Key'!$B$9,1,0)+IF(UPPER(TRIM(L15))='Answer Key'!$B$10,1,0))) | T15: =IF(A15="","",IF(COUNT(N15:S15)<6,"",ROUND(AVERAGE(N15:S15),1))) | U15: =IF(T15="","",INDEX($N$4:$S$4,MATCH(MIN(N15:S15),N15:S15,0))) | V15: =IF(OR(M15="",T15=""),"",IF(M15>=8,IF(T15>=2.5,"Operator","Confident beginner"),IF(T15>=2.5,"Natural","Honest beginner"))) | W15: =IF(V15="","",IF(V15="Operator","Teach. Run the after-action review.",IF(V15="Natural","Vocabulary only. Judgment already transfers.",IF(V15="Honest beginner","The full sequence: terms, then scenarios, then rehearsal.","Scenarios first, autonomy last, whatever their confidence says.")))) | X15: =IF(V15="","",IF(T15>=2.5,"Grant on evidence",IF(T15>=2,"Supervised","Hold")))
M16: =IF(A16="","",IF(COUNTA(C16:L16)<10,"",IF(UPPER(TRIM(C16))='Answer Key'!$B$1,1,0)+IF(UPPER(TRIM(D16))='Answer Key'!$B$2,1,0)+IF(UPPER(TRIM(E16))='Answer Key'!$B$3,1,0)+IF(UPPER(TRIM(F16))='Answer Key'!$B$4,1,0)+IF(UPPER(TRIM(G16))='Answer Key'!$B$5,1,0)+IF(UPPER(TRIM(H16))='Answer Key'!$B$6,1,0)+IF(UPPER(TRIM(I16))='Answer Key'!$B$7,1,0)+IF(UPPER(TRIM(J16))='Answer Key'!$B$8,1,0)+IF(UPPER(TRIM(K16))='Answer Key'!$B$9,1,0)+IF(UPPER(TRIM(L16))='Answer Key'!$B$10,1,0))) | T16: =IF(A16="","",IF(COUNT(N16:S16)<6,"",ROUND(AVERAGE(N16:S16),1))) | U16: =IF(T16="","",INDEX($N$4:$S$4,MATCH(MIN(N16:S16),N16:S16,0))) | V16: =IF(OR(M16="",T16=""),"",IF(M16>=8,IF(T16>=2.5,"Operator","Confident beginner"),IF(T16>=2.5,"Natural","Honest beginner"))) | W16: =IF(V16="","",IF(V16="Operator","Teach. Run the after-action review.",IF(V16="Natural","Vocabulary only. Judgment already transfers.",IF(V16="Honest beginner","The full sequence: terms, then scenarios, then rehearsal.","Scenarios first, autonomy last, whatever their confidence says.")))) | X16: =IF(V16="","",IF(T16>=2.5,"Grant on evidence",IF(T16>=2,"Supervised","Hold")))
M17: =IF(A17="","",IF(COUNTA(C17:L17)<10,"",IF(UPPER(TRIM(C17))='Answer Key'!$B$1,1,0)+IF(UPPER(TRIM(D17))='Answer Key'!$B$2,1,0)+IF(UPPER(TRIM(E17))='Answer Key'!$B$3,1,0)+IF(UPPER(TRIM(F17))='Answer Key'!$B$4,1,0)+IF(UPPER(TRIM(G17))='Answer Key'!$B$5,1,0)+IF(UPPER(TRIM(H17))='Answer Key'!$B$6,1,0)+IF(UPPER(TRIM(I17))='Answer Key'!$B$7,1,0)+IF(UPPER(TRIM(J17))='Answer Key'!$B$8,1,0)+IF(UPPER(TRIM(K17))='Answer Key'!$B$9,1,0)+IF(UPPER(TRIM(L17))='Answer Key'!$B$10,1,0))) | T17: =IF(A17="","",IF(COUNT(N17:S17)<6,"",ROUND(AVERAGE(N17:S17),1))) | U17: =IF(T17="","",INDEX($N$4:$S$4,MATCH(MIN(N17:S17),N17:S17,0))) | V17: =IF(OR(M17="",T17=""),"",IF(M17>=8,IF(T17>=2.5,"Operator","Confident beginner"),IF(T17>=2.5,"Natural","Honest beginner"))) | W17: =IF(V17="","",IF(V17="Operator","Teach. Run the after-action review.",IF(V17="Natural","Vocabulary only. Judgment already transfers.",IF(V17="Honest beginner","The full sequence: terms, then scenarios, then rehearsal.","Scenarios first, autonomy last, whatever their confidence says.")))) | X17: =IF(V17="","",IF(T17>=2.5,"Grant on evidence",IF(T17>=2,"Supervised","Hold")))
M18: =IF(A18="","",IF(COUNTA(C18:L18)<10,"",IF(UPPER(TRIM(C18))='Answer Key'!$B$1,1,0)+IF(UPPER(TRIM(D18))='Answer Key'!$B$2,1,0)+IF(UPPER(TRIM(E18))='Answer Key'!$B$3,1,0)+IF(UPPER(TRIM(F18))='Answer Key'!$B$4,1,0)+IF(UPPER(TRIM(G18))='Answer Key'!$B$5,1,0)+IF(UPPER(TRIM(H18))='Answer Key'!$B$6,1,0)+IF(UPPER(TRIM(I18))='Answer Key'!$B$7,1,0)+IF(UPPER(TRIM(J18))='Answer Key'!$B$8,1,0)+IF(UPPER(TRIM(K18))='Answer Key'!$B$9,1,0)+IF(UPPER(TRIM(L18))='Answer Key'!$B$10,1,0))) | T18: =IF(A18="","",IF(COUNT(N18:S18)<6,"",ROUND(AVERAGE(N18:S18),1))) | U18: =IF(T18="","",INDEX($N$4:$S$4,MATCH(MIN(N18:S18),N18:S18,0))) | V18: =IF(OR(M18="",T18=""),"",IF(M18>=8,IF(T18>=2.5,"Operator","Confident beginner"),IF(T18>=2.5,"Natural","Honest beginner"))) | W18: =IF(V18="","",IF(V18="Operator","Teach. Run the after-action review.",IF(V18="Natural","Vocabulary only. Judgment already transfers.",IF(V18="Honest beginner","The full sequence: terms, then scenarios, then rehearsal.","Scenarios first, autonomy last, whatever their confidence says.")))) | X18: =IF(V18="","",IF(T18>=2.5,"Grant on evidence",IF(T18>=2,"Supervised","Hold")))
M19: =IF(A19="","",IF(COUNTA(C19:L19)<10,"",IF(UPPER(TRIM(C19))='Answer Key'!$B$1,1,0)+IF(UPPER(TRIM(D19))='Answer Key'!$B$2,1,0)+IF(UPPER(TRIM(E19))='Answer Key'!$B$3,1,0)+IF(UPPER(TRIM(F19))='Answer Key'!$B$4,1,0)+IF(UPPER(TRIM(G19))='Answer Key'!$B$5,1,0)+IF(UPPER(TRIM(H19))='Answer Key'!$B$6,1,0)+IF(UPPER(TRIM(I19))='Answer Key'!$B$7,1,0)+IF(UPPER(TRIM(J19))='Answer Key'!$B$8,1,0)+IF(UPPER(TRIM(K19))='Answer Key'!$B$9,1,0)+IF(UPPER(TRIM(L19))='Answer Key'!$B$10,1,0))) | T19: =IF(A19="","",IF(COUNT(N19:S19)<6,"",ROUND(AVERAGE(N19:S19),1))) | U19: =IF(T19="","",INDEX($N$4:$S$4,MATCH(MIN(N19:S19),N19:S19,0))) | V19: =IF(OR(M19="",T19=""),"",IF(M19>=8,IF(T19>=2.5,"Operator","Confident beginner"),IF(T19>=2.5,"Natural","Honest beginner"))) | W19: =IF(V19="","",IF(V19="Operator","Teach. Run the after-action review.",IF(V19="Natural","Vocabulary only. Judgment already transfers.",IF(V19="Honest beginner","The full sequence: terms, then scenarios, then rehearsal.","Scenarios first, autonomy last, whatever their confidence says.")))) | X19: =IF(V19="","",IF(T19>=2.5,"Grant on evidence",IF(T19>=2,"Supervised","Hold")))
M20: =IF(A20="","",IF(COUNTA(C20:L20)<10,"",IF(UPPER(TRIM(C20))='Answer Key'!$B$1,1,0)+IF(UPPER(TRIM(D20))='Answer Key'!$B$2,1,0)+IF(UPPER(TRIM(E20))='Answer Key'!$B$3,1,0)+IF(UPPER(TRIM(F20))='Answer Key'!$B$4,1,0)+IF(UPPER(TRIM(G20))='Answer Key'!$B$5,1,0)+IF(UPPER(TRIM(H20))='Answer Key'!$B$6,1,0)+IF(UPPER(TRIM(I20))='Answer Key'!$B$7,1,0)+IF(UPPER(TRIM(J20))='Answer Key'!$B$8,1,0)+IF(UPPER(TRIM(K20))='Answer Key'!$B$9,1,0)+IF(UPPER(TRIM(L20))='Answer Key'!$B$10,1,0))) | T20: =IF(A20="","",IF(COUNT(N20:S20)<6,"",ROUND(AVERAGE(N20:S20),1))) | U20: =IF(T20="","",INDEX($N$4:$S$4,MATCH(MIN(N20:S20),N20:S20,0))) | V20: =IF(OR(M20="",T20=""),"",IF(M20>=8,IF(T20>=2.5,"Operator","Confident beginner"),IF(T20>=2.5,"Natural","Honest beginner"))) | W20: =IF(V20="","",IF(V20="Operator","Teach. Run the after-action review.",IF(V20="Natural","Vocabulary only. Judgment already transfers.",IF(V20="Honest beginner","The full sequence: terms, then scenarios, then rehearsal.","Scenarios first, autonomy last, whatever their confidence says.")))) | X20: =IF(V20="","",IF(T20>=2.5,"Grant on evidence",IF(T20>=2,"Supervised","Hold")))
M21: =IF(A21="","",IF(COUNTA(C21:L21)<10,"",IF(UPPER(TRIM(C21))='Answer Key'!$B$1,1,0)+IF(UPPER(TRIM(D21))='Answer Key'!$B$2,1,0)+IF(UPPER(TRIM(E21))='Answer Key'!$B$3,1,0)+IF(UPPER(TRIM(F21))='Answer Key'!$B$4,1,0)+IF(UPPER(TRIM(G21))='Answer Key'!$B$5,1,0)+IF(UPPER(TRIM(H21))='Answer Key'!$B$6,1,0)+IF(UPPER(TRIM(I21))='Answer Key'!$B$7,1,0)+IF(UPPER(TRIM(J21))='Answer Key'!$B$8,1,0)+IF(UPPER(TRIM(K21))='Answer Key'!$B$9,1,0)+IF(UPPER(TRIM(L21))='Answer Key'!$B$10,1,0))) | T21: =IF(A21="","",IF(COUNT(N21:S21)<6,"",ROUND(AVERAGE(N21:S21),1))) | U21: =IF(T21="","",INDEX($N$4:$S$4,MATCH(MIN(N21:S21),N21:S21,0))) | V21: =IF(OR(M21="",T21=""),"",IF(M21>=8,IF(T21>=2.5,"Operator","Confident beginner"),IF(T21>=2.5,"Natural","Honest beginner"))) | W21: =IF(V21="","",IF(V21="Operator","Teach. Run the after-action review.",IF(V21="Natural","Vocabulary only. Judgment already transfers.",IF(V21="Honest beginner","The full sequence: terms, then scenarios, then rehearsal.","Scenarios first, autonomy last, whatever their confidence says.")))) | X21: =IF(V21="","",IF(T21>=2.5,"Grant on evidence",IF(T21>=2,"Supervised","Hold")))
M22: =IF(A22="","",IF(COUNTA(C22:L22)<10,"",IF(UPPER(TRIM(C22))='Answer Key'!$B$1,1,0)+IF(UPPER(TRIM(D22))='Answer Key'!$B$2,1,0)+IF(UPPER(TRIM(E22))='Answer Key'!$B$3,1,0)+IF(UPPER(TRIM(F22))='Answer Key'!$B$4,1,0)+IF(UPPER(TRIM(G22))='Answer Key'!$B$5,1,0)+IF(UPPER(TRIM(H22))='Answer Key'!$B$6,1,0)+IF(UPPER(TRIM(I22))='Answer Key'!$B$7,1,0)+IF(UPPER(TRIM(J22))='Answer Key'!$B$8,1,0)+IF(UPPER(TRIM(K22))='Answer Key'!$B$9,1,0)+IF(UPPER(TRIM(L22))='Answer Key'!$B$10,1,0))) | T22: =IF(A22="","",IF(COUNT(N22:S22)<6,"",ROUND(AVERAGE(N22:S22),1))) | U22: =IF(T22="","",INDEX($N$4:$S$4,MATCH(MIN(N22:S22),N22:S22,0))) | V22: =IF(OR(M22="",T22=""),"",IF(M22>=8,IF(T22>=2.5,"Operator","Confident beginner"),IF(T22>=2.5,"Natural","Honest beginner"))) | W22: =IF(V22="","",IF(V22="Operator","Teach. Run the after-action review.",IF(V22="Natural","Vocabulary only. Judgment already transfers.",IF(V22="Honest beginner","The full sequence: terms, then scenarios, then rehearsal.","Scenarios first, autonomy last, whatever their confidence says.")))) | X22: =IF(V22="","",IF(T22>=2.5,"Grant on evidence",IF(T22>=2,"Supervised","Hold")))
M23: =IF(A23="","",IF(COUNTA(C23:L23)<10,"",IF(UPPER(TRIM(C23))='Answer Key'!$B$1,1,0)+IF(UPPER(TRIM(D23))='Answer Key'!$B$2,1,0)+IF(UPPER(TRIM(E23))='Answer Key'!$B$3,1,0)+IF(UPPER(TRIM(F23))='Answer Key'!$B$4,1,0)+IF(UPPER(TRIM(G23))='Answer Key'!$B$5,1,0)+IF(UPPER(TRIM(H23))='Answer Key'!$B$6,1,0)+IF(UPPER(TRIM(I23))='Answer Key'!$B$7,1,0)+IF(UPPER(TRIM(J23))='Answer Key'!$B$8,1,0)+IF(UPPER(TRIM(K23))='Answer Key'!$B$9,1,0)+IF(UPPER(TRIM(L23))='Answer Key'!$B$10,1,0))) | T23: =IF(A23="","",IF(COUNT(N23:S23)<6,"",ROUND(AVERAGE(N23:S23),1))) | U23: =IF(T23="","",INDEX($N$4:$S$4,MATCH(MIN(N23:S23),N23:S23,0))) | V23: =IF(OR(M23="",T23=""),"",IF(M23>=8,IF(T23>=2.5,"Operator","Confident beginner"),IF(T23>=2.5,"Natural","Honest beginner"))) | W23: =IF(V23="","",IF(V23="Operator","Teach. Run the after-action review.",IF(V23="Natural","Vocabulary only. Judgment already transfers.",IF(V23="Honest beginner","The full sequence: terms, then scenarios, then rehearsal.","Scenarios first, autonomy last, whatever their confidence says.")))) | X23: =IF(V23="","",IF(T23>=2.5,"Grant on evidence",IF(T23>=2,"Supervised","Hold")))
M24: =IF(A24="","",IF(COUNTA(C24:L24)<10,"",IF(UPPER(TRIM(C24))='Answer Key'!$B$1,1,0)+IF(UPPER(TRIM(D24))='Answer Key'!$B$2,1,0)+IF(UPPER(TRIM(E24))='Answer Key'!$B$3,1,0)+IF(UPPER(TRIM(F24))='Answer Key'!$B$4,1,0)+IF(UPPER(TRIM(G24))='Answer Key'!$B$5,1,0)+IF(UPPER(TRIM(H24))='Answer Key'!$B$6,1,0)+IF(UPPER(TRIM(I24))='Answer Key'!$B$7,1,0)+IF(UPPER(TRIM(J24))='Answer Key'!$B$8,1,0)+IF(UPPER(TRIM(K24))='Answer Key'!$B$9,1,0)+IF(UPPER(TRIM(L24))='Answer Key'!$B$10,1,0))) | T24: =IF(A24="","",IF(COUNT(N24:S24)<6,"",ROUND(AVERAGE(N24:S24),1))) | U24: =IF(T24="","",INDEX($N$4:$S$4,MATCH(MIN(N24:S24),N24:S24,0))) | V24: =IF(OR(M24="",T24=""),"",IF(M24>=8,IF(T24>=2.5,"Operator","Confident beginner"),IF(T24>=2.5,"Natural","Honest beginner"))) | W24: =IF(V24="","",IF(V24="Operator","Teach. Run the after-action review.",IF(V24="Natural","Vocabulary only. Judgment already transfers.",IF(V24="Honest beginner","The full sequence: terms, then scenarios, then rehearsal.","Scenarios first, autonomy last, whatever their confidence says.")))) | X24: =IF(V24="","",IF(T24>=2.5,"Grant on evidence",IF(T24>=2,"Supervised","Hold")))
... M44: =IF(A44="","",IF(COUNTA(C44:L44)<10,"",IF(UPPER(TRIM(C44))='Answer Key'!$B$1,1,0)+IF(UPPER(TRIM(D44))='Answer Key'!$B$2,1,0)+IF(UPPER(TRIM(E44))='Answer Key'!$B$3,1,0)+IF(UPPER(TRIM(F44))='Answer Key'!$B$4,1,0)+IF(UPPER(TRIM(G44))='Answer Key'!$B$5,1,0)+IF(UPPER(TRIM(H44))='Answer Key'!$B$6,1,0)+IF(UPPER(TRIM(I44))='Answer Key'!$B$7,1,0)+IF(UPPER(TRIM(J44))='Answer Key'!$B$8,1,0)+IF(UPPER(TRIM(K44))='Answer Key'!$B$9,1,0)+IF(UPPER(TRIM(L44))='Answer Key'!$B$10,1,0))) | T44: =IF(A44="","",IF(COUNT(N44:S44)<6,"",ROUND(AVERAGE(N44:S44),1))) | U44: =IF(T44="","",INDEX($N$4:$S$4,MATCH(MIN(N44:S44),N44:S44,0))) | V44: =IF(OR(M44="",T44=""),"",IF(M44>=8,IF(T44>=2.5,"Operator","Confident beginner"),IF(T44>=2.5,"Natural","Honest beginner"))) | W44: =IF(V44="","",IF(V44="Operator","Teach. Run the after-action review.",IF(V44="Natural","Vocabulary only. Judgment already transfers.",IF(V44="Honest beginner","The full sequence: terms, then scenarios, then rehearsal.","Scenarios first, autonomy last, whatever their confidence says.")))) | X44: =IF(V44="","",IF(T44>=2.5,"Grant on evidence",IF(T44>=2,"Supervised","Hold")))
A47: TEAM SUMMARY
A48: People mapped | B48: =COUNTIF(A5:A44,"?*")
A49: Operators | B49: =COUNTIF(V5:V44,"Operator")
A50: Naturals | B50: =COUNTIF(V5:V44,"Natural")
A51: Honest beginners | B51: =COUNTIF(V5:V44,"Honest beginner")
A52: Confident beginners | B52: =COUNTIF(V5:V44,"Confident beginner")
A53: Average literacy (of 10) | B53: =IFERROR(ROUND(AVERAGE(M5:M44),1),"")
A54: Average capability (of 3) | B54: =IFERROR(ROUND(AVERAGE(T5:T44),1),"")
A56: Team average by skill
A57: Delegation | B57: =IFERROR(ROUND(AVERAGE(N5:N44),1),"")
A58: Inquiry | B58: =IFERROR(ROUND(AVERAGE(O5:O44),1),"")
A59: Output interrogation | B59: =IFERROR(ROUND(AVERAGE(P5:P44),1),"")
A60: Verification judgment | B60: =IFERROR(ROUND(AVERAGE(Q5:Q44),1),"")
A61: Coaching | B61: =IFERROR(ROUND(AVERAGE(R5:R44),1),"")
A62: Reinvestment discipline | B62: =IFERROR(ROUND(AVERAGE(S5:S44),1),"")
...
