Workbook

Sheet How to Use
B1: The Manager Readiness Review
B2: From AI Will Scale Good Leadership and Bad Leadership: The CHRO’s Method for Redesigning Work Before AI Scales What’s Broken, by Liz Corey | Toolbox No. 9 | OnTheGrow Leadership
B3: © 2026 Elizabeth A. Corey. All rights reserved. GROWTH Execution Model™. onthegrow.ai
B5: Never scale what you haven’t reviewed. Never review what you’re not willing to repair. This is a talent review for the management layer, run before any pilot multiplies. It answers one question for every manager who will run this at scale: can this person hold it at volume?
B7: HOW THIS WORKBOOK IS SET UP
B8: Review | C8: One row per manager. Score six behaviors Yes, Sometimes, or No from the last ninety days, with the evidence written beside each. The workbook scores, sets the disposition, and names the next action.
B9: Rollout Decision | C9: The one page for the rollout meeting: the two evidence gates, headcount by disposition, which behavior fails most, and the three lists.
B10: Example rows | C10: Ten managers from a sample rollout are filled in so you can see a finished review. Replace them with your own.
B11: Yellow cells | C11: Type in the yellow cells only. Every other cell is a formula.
B13: THE SIX BEHAVIORS
B14: 1. Sets written standards | C14: A written expectation of what good output looks like, for a person and for an agent. Not a feeling.
B15: 2. Catches confident errors | C15: Spots the error the system produced fluently, formatted, on time. The new skill, and the one most managers have never practiced.
B16: 3. Overrides and can say why | C16: The system recommends. The manager decides, and can explain why they overruled it, or why they did not.
B17: 4. Delivers feedback before it piles up | C17: Has the hard conversation early. At machine speed the pileup arrives in a week, not a quarter.
B18: 5. Runs a consistent conversation | C18: Runs the fortieth conversation the way they ran the first. Consistency takes a structure, not a memory.
B19: 6. Coaches and develops, people and agents both | C19: Tells a person, and an agent, what went wrong, what good looked like, and what changes next time.
B21: HOW TO RUN IT
B22: 1. Name the population | C22: Every manager whose team the rollout will reach and the pilot did not. Pilots run on volunteers. Rollouts run on everyone.
B23: 2. Score from evidence | C23: Six behaviors, each Yes, Sometimes, or No, from the last ninety days. Not reputation. Write the evidence in the cell beside the score. A blank evidence cell is a reputation score.
B24: 3. Bring two pieces of evidence | C24: Proof that the knowledge the rollout touches has passed the readiness test, and proof that every consequential rule it will run has a named owner. If either is missing, the best manager in the building cannot hold it.
B25: 4. Sort into three dispositions | C25: Ready: scale now, and scale loudly. Ready with support: scale with a named coach and a date. Not yet: keep the rollout at pilot scope for that team until the gap closes. Not yet does not mean cancel. It means contain.
B26: 5. Publish the decision with the evidence attached | C26: A rollout that cannot pass the review in writing was never ready. It was just enthusiastic.
B28: HOW IT SCORES
B29: Behavior score | C29: Yes is 1, Sometimes is 0.5, No is 0, out of 6.
B30: Ready | C30: 5 or more, with no No answers.
B31: Ready with support | C31: 3.5 to 4.5, or exactly one No. Needs a named coach and a date.
B32: Not yet | C32: Below 3.5, or two or more No answers. Hold at pilot scope until the gap closes.
B33: Override | C33: The score is a starting point. The reviewer can set the disposition by hand in the Disposition override column, and the workbook will use it. Write why in the notes.
B35: THE CHRO’S MOVE
B36: Get there first | C36: The process you redesigned is about to generate its rollout conversation. Run this review yourself, manager by manager, before anyone says the triumphant sentence. Then bring the Rollout Decision page to the meeting and put it next to the enthusiasm. You will have changed the question in the room from how fast can we roll this out to who is ready to run it.
B38: WANT IT DONE FASTER?
B39: AI Management Simulation | C39: Twelve managers work the same scenarios with their own AI tools, scored against the six behaviors and the GROWTH standard. The review fills itself in from what they actually did. Early access. Call for pricing. Book a conversation at onthegrow.ai
B41: © 2026 Elizabeth A. Corey. All rights reserved. GROWTH Execution Model™. onthegrow.ai

Sheet Review
A1: Manager Readiness Review
A2: HOW TO USE THIS TAB: One row per manager. For each behavior, pick Yes, Sometimes, or No and write the evidence from the last ninety days beside it. Teal columns calculate. Use the override column only when you disagree with the score, and say why in the notes. The rows are an example; replace them.
A3: © 2026 Elizabeth A. Corey. All rights reserved. GROWTH Execution Model™. onthegrow.ai
A4: Manager | B4: Team | C4: People the rollout reaches | D4: Sets written standards | E4: Evidence (last 90 days) | F4: Catches confident errors | G4: Evidence (last 90 days) | H4: Overrides and can say why | I4: Evidence (last 90 days) | J4: Delivers feedback before it piles up | K4: Evidence (last 90 days) | L4: Runs a consistent conversation | M4: Evidence (last 90 days) | N4: Coaches and develops, people and agents both | O4: Evidence (last 90 days) | P4: Behavior score (of 6) | Q4: No answers | R4: Evidence missing | S4: Suggested disposition | T4: Disposition override | U4: Disposition | V4: Named coach | W4: Date | X4: Next action | Y4: Notes
A5: Service team lead | B5: Customer service, east | C5: 14 | D5: Yes | E5: Scorecard posted and used in reviews | F5: Yes | G5: Flagged a wrong policy citation in an AI draft in August | H5: Yes | I5: Documented two overrides with reasons | J5: Yes | K5: Two feedback conversations in the quarter, both within a week | L5: Yes | M5: Uses the same agenda every 1:1 | N5: Sometimes | O5: Runs development talks; has not yet coached the agent | P5: =IF(A5="","",IF(COUNTA(D5)+COUNTA(F5)+COUNTA(H5)+COUNTA(J5)+COUNTA(L5)+COUNTA(N5)<6,"",IF(D5="Yes",1,IF(D5="Sometimes",0.5,0))+IF(F5="Yes",1,IF(F5="Sometimes",0.5,0))+IF(H5="Yes",1,IF(H5="Sometimes",0.5,0))+IF(J5="Yes",1,IF(J5="Sometimes",0.5,0))+IF(L5="Yes",1,IF(L5="Sometimes",0.5,0))+IF(N5="Yes",1,IF(N5="Sometimes",0.5,0)))) | Q5: =IF(P5="","",IF(D5="No",1,0)+IF(F5="No",1,0)+IF(H5="No",1,0)+IF(J5="No",1,0)+IF(L5="No",1,0)+IF(N5="No",1,0)) | R5: =IF(A5="","",6-COUNTA(E5)-COUNTA(G5)-COUNTA(I5)-COUNTA(K5)-COUNTA(M5)-COUNTA(O5)) | S5: =IF(P5="","",IF(OR(P5<3.5,Q5>=2),"Not yet",IF(AND(P5>=5,Q5=0),"Ready","Ready with support"))) | U5: =IF(A5="","",IF(T5<>"",T5,S5)) | X5: =IF(A5="","",IF(P5="","Score all six behaviors.",IF(R5>0,"Write the evidence. A blank evidence cell is a reputation score.",IF(U5="Ready","Scale now, and scale loudly.",IF(U5="Not yet","Hold at pilot scope until the gap closes. Name what closes it.",IF(V5="","Name a coach.",IF(W5="","Set a date.","Scale with support. Review on the date.")))))))
A6: Regional operations manager | B6: Operations, north | C6: 22 | D6: Yes | E6: Written standards for every role | F6: Sometimes | G6: Caught one of two seeded errors | H6: Yes | I6: Overrode agent on a scheduling call and logged why | J6: Sometimes | K6: One conversation waited six weeks | L6: Yes | M6: Same structure across all 1:1s | N6: Yes | O6: Coached the scheduling agent after a bad week | P6: =IF(A6="","",IF(COUNTA(D6)+COUNTA(F6)+COUNTA(H6)+COUNTA(J6)+COUNTA(L6)+COUNTA(N6)<6,"",IF(D6="Yes",1,IF(D6="Sometimes",0.5,0))+IF(F6="Yes",1,IF(F6="Sometimes",0.5,0))+IF(H6="Yes",1,IF(H6="Sometimes",0.5,0))+IF(J6="Yes",1,IF(J6="Sometimes",0.5,0))+IF(L6="Yes",1,IF(L6="Sometimes",0.5,0))+IF(N6="Yes",1,IF(N6="Sometimes",0.5,0)))) | Q6: =IF(P6="","",IF(D6="No",1,0)+IF(F6="No",1,0)+IF(H6="No",1,0)+IF(J6="No",1,0)+IF(L6="No",1,0)+IF(N6="No",1,0)) | R6: =IF(A6="","",6-COUNTA(E6)-COUNTA(G6)-COUNTA(I6)-COUNTA(K6)-COUNTA(M6)-COUNTA(O6)) | S6: =IF(P6="","",IF(OR(P6<3.5,Q6>=2),"Not yet",IF(AND(P6>=5,Q6=0),"Ready","Ready with support"))) | U6: =IF(A6="","",IF(T6<>"",T6,S6)) | X6: =IF(A6="","",IF(P6="","Score all six behaviors.",IF(R6>0,"Write the evidence. A blank evidence cell is a reputation score.",IF(U6="Ready","Scale now, and scale loudly.",IF(U6="Not yet","Hold at pilot scope until the gap closes. Name what closes it.",IF(V6="","Name a coach.",IF(W6="","Set a date.","Scale with support. Review on the date.")))))))
A7: Recruiting manager | B7: Talent acquisition | C7: 9 | D7: Yes | E7: Performance profiles written for every open role | F7: Yes | G7: Rejected an AI shortlist that screened out a strong applicant | H7: Yes | I7: Documents every override in the ATS | J7: Yes | K7: Weekly feedback cadence | L7: Yes | M7: GROWTH agenda in every 1:1 | N7: Yes | O7: Runs after-action reviews with the team and the agent | P7: =IF(A7="","",IF(COUNTA(D7)+COUNTA(F7)+COUNTA(H7)+COUNTA(J7)+COUNTA(L7)+COUNTA(N7)<6,"",IF(D7="Yes",1,IF(D7="Sometimes",0.5,0))+IF(F7="Yes",1,IF(F7="Sometimes",0.5,0))+IF(H7="Yes",1,IF(H7="Sometimes",0.5,0))+IF(J7="Yes",1,IF(J7="Sometimes",0.5,0))+IF(L7="Yes",1,IF(L7="Sometimes",0.5,0))+IF(N7="Yes",1,IF(N7="Sometimes",0.5,0)))) | Q7: =IF(P7="","",IF(D7="No",1,0)+IF(F7="No",1,0)+IF(H7="No",1,0)+IF(J7="No",1,0)+IF(L7="No",1,0)+IF(N7="No",1,0)) | R7: =IF(A7="","",6-COUNTA(E7)-COUNTA(G7)-COUNTA(I7)-COUNTA(K7)-COUNTA(M7)-COUNTA(O7)) | S7: =IF(P7="","",IF(OR(P7<3.5,Q7>=2),"Not yet",IF(AND(P7>=5,Q7=0),"Ready","Ready with support"))) | U7: =IF(A7="","",IF(T7<>"",T7,S7)) | X7: =IF(A7="","",IF(P7="","Score all six behaviors.",IF(R7>0,"Write the evidence. A blank evidence cell is a reputation score.",IF(U7="Ready","Scale now, and scale loudly.",IF(U7="Not yet","Hold at pilot scope until the gap closes. Name what closes it.",IF(V7="","Name a coach.",IF(W7="","Set a date.","Scale with support. Review on the date.")))))))
A8: Payroll supervisor | B8: Finance shared services | C8: 11 | D8: Sometimes | E8: Standards exist for some tasks, not all | F8: No | G8: Forwarded the fabricated citation without checking it | H8: Sometimes | I8: Accepts system output by default | J8: Yes | K8: Raises issues quickly | L8: Yes | M8: Consistent 1:1 structure | N8: Sometimes | O8: Develops people; agent coaching not started | P8: =IF(A8="","",IF(COUNTA(D8)+COUNTA(F8)+COUNTA(H8)+COUNTA(J8)+COUNTA(L8)+COUNTA(N8)<6,"",IF(D8="Yes",1,IF(D8="Sometimes",0.5,0))+IF(F8="Yes",1,IF(F8="Sometimes",0.5,0))+IF(H8="Yes",1,IF(H8="Sometimes",0.5,0))+IF(J8="Yes",1,IF(J8="Sometimes",0.5,0))+IF(L8="Yes",1,IF(L8="Sometimes",0.5,0))+IF(N8="Yes",1,IF(N8="Sometimes",0.5,0)))) | Q8: =IF(P8="","",IF(D8="No",1,0)+IF(F8="No",1,0)+IF(H8="No",1,0)+IF(J8="No",1,0)+IF(L8="No",1,0)+IF(N8="No",1,0)) | R8: =IF(A8="","",6-COUNTA(E8)-COUNTA(G8)-COUNTA(I8)-COUNTA(K8)-COUNTA(M8)-COUNTA(O8)) | S8: =IF(P8="","",IF(OR(P8<3.5,Q8>=2),"Not yet",IF(AND(P8>=5,Q8=0),"Ready","Ready with support"))) | U8: =IF(A8="","",IF(T8<>"",T8,S8)) | V8: Recruiting manager | W8: 46418 | X8: =IF(A8="","",IF(P8="","Score all six behaviors.",IF(R8>0,"Write the evidence. A blank evidence cell is a reputation score.",IF(U8="Ready","Scale now, and scale loudly.",IF(U8="Not yet","Hold at pilot scope until the gap closes. Name what closes it.",IF(V8="","Name a coach.",IF(W8="","Set a date.","Scale with support. Review on the date."))))))) | Y8: Forwarded the fabricated citation. One No, and it is the one that matters most at volume.
A9: Benefits manager | B9: HR operations | C9: 7 | D9: Sometimes | E9: SLAs written for some case types, not all | F9: Yes | G9: Caught the seeded enrollment error | H9: Sometimes | I9: Overrides, but reasons are not always written | J9: Sometimes | K9: Feedback is prompt with some people, slow with others | L9: Yes | M9: Same agenda every week | N9: Yes | O9: Coaches people and reviews agent samples weekly | P9: =IF(A9="","",IF(COUNTA(D9)+COUNTA(F9)+COUNTA(H9)+COUNTA(J9)+COUNTA(L9)+COUNTA(N9)<6,"",IF(D9="Yes",1,IF(D9="Sometimes",0.5,0))+IF(F9="Yes",1,IF(F9="Sometimes",0.5,0))+IF(H9="Yes",1,IF(H9="Sometimes",0.5,0))+IF(J9="Yes",1,IF(J9="Sometimes",0.5,0))+IF(L9="Yes",1,IF(L9="Sometimes",0.5,0))+IF(N9="Yes",1,IF(N9="Sometimes",0.5,0)))) | Q9: =IF(P9="","",IF(D9="No",1,0)+IF(F9="No",1,0)+IF(H9="No",1,0)+IF(J9="No",1,0)+IF(L9="No",1,0)+IF(N9="No",1,0)) | R9: =IF(A9="","",6-COUNTA(E9)-COUNTA(G9)-COUNTA(I9)-COUNTA(K9)-COUNTA(M9)-COUNTA(O9)) | S9: =IF(P9="","",IF(OR(P9<3.5,Q9>=2),"Not yet",IF(AND(P9>=5,Q9=0),"Ready","Ready with support"))) | U9: =IF(A9="","",IF(T9<>"",T9,S9)) | V9: Service team lead | W9: 46418 | X9: =IF(A9="","",IF(P9="","Score all six behaviors.",IF(R9>0,"Write the evidence. A blank evidence cell is a reputation score.",IF(U9="Ready","Scale now, and scale loudly.",IF(U9="Not yet","Hold at pilot scope until the gap closes. Name what closes it.",IF(V9="","Name a coach.",IF(W9="","Set a date.","Scale with support. Review on the date.")))))))
A10: Plant HR generalist lead | B10: HR, plant A | C10: 18 | D10: Sometimes | E10: Standards live in the lead's head | F10: Sometimes | G10: Caught one seeded error of two | H10: No | I10: Cannot say why the agent was or was not overruled | J10: Sometimes | K10: Feedback tends to wait for the review cycle | L10: Sometimes | M10: Structure varies by person | N10: Sometimes | O10: Informal development only | P10: =IF(A10="","",IF(COUNTA(D10)+COUNTA(F10)+COUNTA(H10)+COUNTA(J10)+COUNTA(L10)+COUNTA(N10)<6,"",IF(D10="Yes",1,IF(D10="Sometimes",0.5,0))+IF(F10="Yes",1,IF(F10="Sometimes",0.5,0))+IF(H10="Yes",1,IF(H10="Sometimes",0.5,0))+IF(J10="Yes",1,IF(J10="Sometimes",0.5,0))+IF(L10="Yes",1,IF(L10="Sometimes",0.5,0))+IF(N10="Yes",1,IF(N10="Sometimes",0.5,0)))) | Q10: =IF(P10="","",IF(D10="No",1,0)+IF(F10="No",1,0)+IF(H10="No",1,0)+IF(J10="No",1,0)+IF(L10="No",1,0)+IF(N10="No",1,0)) | R10: =IF(A10="","",6-COUNTA(E10)-COUNTA(G10)-COUNTA(I10)-COUNTA(K10)-COUNTA(M10)-COUNTA(O10)) | S10: =IF(P10="","",IF(OR(P10<3.5,Q10>=2),"Not yet",IF(AND(P10>=5,Q10=0),"Ready","Ready with support"))) | U10: =IF(A10="","",IF(T10<>"",T10,S10)) | X10: =IF(A10="","",IF(P10="","Score all six behaviors.",IF(R10>0,"Write the evidence. A blank evidence cell is a reputation score.",IF(U10="Ready","Scale now, and scale loudly.",IF(U10="Not yet","Hold at pilot scope until the gap closes. Name what closes it.",IF(V10="","Name a coach.",IF(W10="","Set a date.","Scale with support. Review on the date.")))))))
A11: Accounts payable supervisor | B11: Finance shared services | C11: 12 | D11: Yes | E11: Written approval standards | F11: Yes | G11: Caught both seeded errors | H11: Yes | I11: Overrides with a note every time | J11: Sometimes | K11: Feedback sometimes waits for month end | L11: Sometimes | M11: Agenda drifts under volume | N11: Sometimes | O11: Develops people; no agent coaching yet | P11: =IF(A11="","",IF(COUNTA(D11)+COUNTA(F11)+COUNTA(H11)+COUNTA(J11)+COUNTA(L11)+COUNTA(N11)<6,"",IF(D11="Yes",1,IF(D11="Sometimes",0.5,0))+IF(F11="Yes",1,IF(F11="Sometimes",0.5,0))+IF(H11="Yes",1,IF(H11="Sometimes",0.5,0))+IF(J11="Yes",1,IF(J11="Sometimes",0.5,0))+IF(L11="Yes",1,IF(L11="Sometimes",0.5,0))+IF(N11="Yes",1,IF(N11="Sometimes",0.5,0)))) | Q11: =IF(P11="","",IF(D11="No",1,0)+IF(F11="No",1,0)+IF(H11="No",1,0)+IF(J11="No",1,0)+IF(L11="No",1,0)+IF(N11="No",1,0)) | R11: =IF(A11="","",6-COUNTA(E11)-COUNTA(G11)-COUNTA(I11)-COUNTA(K11)-COUNTA(M11)-COUNTA(O11)) | S11: =IF(P11="","",IF(OR(P11<3.5,Q11>=2),"Not yet",IF(AND(P11>=5,Q11=0),"Ready","Ready with support"))) | U11: =IF(A11="","",IF(T11<>"",T11,S11)) | V11: Customer onboarding lead | W11: 46446 | X11: =IF(A11="","",IF(P11="","Score all six behaviors.",IF(R11>0,"Write the evidence. A blank evidence cell is a reputation score.",IF(U11="Ready","Scale now, and scale loudly.",IF(U11="Not yet","Hold at pilot scope until the gap closes. Name what closes it.",IF(V11="","Name a coach.",IF(W11="","Set a date.","Scale with support. Review on the date.")))))))
A12: Field sales manager | B12: Sales, west | C12: 16 | D12: Sometimes | E12: Targets are written; quality standards are not | F12: Yes | G12: Caught an AI pricing error before it reached a customer | H12: Yes | I12: Overrides often and explains why | J12: Yes | K12: Direct and early with feedback | L12: No | M12: Every 1:1 is different | N12: Sometimes | O12: Coaches deals, not development | P12: =IF(A12="","",IF(COUNTA(D12)+COUNTA(F12)+COUNTA(H12)+COUNTA(J12)+COUNTA(L12)+COUNTA(N12)<6,"",IF(D12="Yes",1,IF(D12="Sometimes",0.5,0))+IF(F12="Yes",1,IF(F12="Sometimes",0.5,0))+IF(H12="Yes",1,IF(H12="Sometimes",0.5,0))+IF(J12="Yes",1,IF(J12="Sometimes",0.5,0))+IF(L12="Yes",1,IF(L12="Sometimes",0.5,0))+IF(N12="Yes",1,IF(N12="Sometimes",0.5,0)))) | Q12: =IF(P12="","",IF(D12="No",1,0)+IF(F12="No",1,0)+IF(H12="No",1,0)+IF(J12="No",1,0)+IF(L12="No",1,0)+IF(N12="No",1,0)) | R12: =IF(A12="","",6-COUNTA(E12)-COUNTA(G12)-COUNTA(I12)-COUNTA(K12)-COUNTA(M12)-COUNTA(O12)) | S12: =IF(P12="","",IF(OR(P12<3.5,Q12>=2),"Not yet",IF(AND(P12>=5,Q12=0),"Ready","Ready with support"))) | U12: =IF(A12="","",IF(T12<>"",T12,S12)) | V12: Recruiting manager | W12: 46418 | X12: =IF(A12="","",IF(P12="","Score all six behaviors.",IF(R12>0,"Write the evidence. A blank evidence cell is a reputation score.",IF(U12="Ready","Scale now, and scale loudly.",IF(U12="Not yet","Hold at pilot scope until the gap closes. Name what closes it.",IF(V12="","Name a coach.",IF(W12="","Set a date.","Scale with support. Review on the date.")))))))
A13: Customer onboarding lead | B13: Customer success | C13: 10 | D13: Yes | E13: Written onboarding standard | F13: Yes | G13: Caught a wrong contract term in an AI summary | H13: Yes | I13: Logs overrides | J13: Yes | K13: Weekly feedback | L13: Sometimes | M13: Mostly consistent; drifts when travelling | N13: Yes | O13: Coaches people and the onboarding agent | P13: =IF(A13="","",IF(COUNTA(D13)+COUNTA(F13)+COUNTA(H13)+COUNTA(J13)+COUNTA(L13)+COUNTA(N13)<6,"",IF(D13="Yes",1,IF(D13="Sometimes",0.5,0))+IF(F13="Yes",1,IF(F13="Sometimes",0.5,0))+IF(H13="Yes",1,IF(H13="Sometimes",0.5,0))+IF(J13="Yes",1,IF(J13="Sometimes",0.5,0))+IF(L13="Yes",1,IF(L13="Sometimes",0.5,0))+IF(N13="Yes",1,IF(N13="Sometimes",0.5,0)))) | Q13: =IF(P13="","",IF(D13="No",1,0)+IF(F13="No",1,0)+IF(H13="No",1,0)+IF(J13="No",1,0)+IF(L13="No",1,0)+IF(N13="No",1,0)) | R13: =IF(A13="","",6-COUNTA(E13)-COUNTA(G13)-COUNTA(I13)-COUNTA(K13)-COUNTA(M13)-COUNTA(O13)) | S13: =IF(P13="","",IF(OR(P13<3.5,Q13>=2),"Not yet",IF(AND(P13>=5,Q13=0),"Ready","Ready with support"))) | U13: =IF(A13="","",IF(T13<>"",T13,S13)) | X13: =IF(A13="","",IF(P13="","Score all six behaviors.",IF(R13>0,"Write the evidence. A blank evidence cell is a reputation score.",IF(U13="Ready","Scale now, and scale loudly.",IF(U13="Not yet","Hold at pilot scope until the gap closes. Name what closes it.",IF(V13="","Name a coach.",IF(W13="","Set a date.","Scale with support. Review on the date.")))))))
A14: Warehouse shift manager | B14: Operations, south | C14: 25 | D14: No | E14: No written standards | F14: No | G14: Did not check either seeded error | H14: Sometimes | I14: Follows the system | J14: Yes | K14: Quick to raise issues | L14: Sometimes | M14: Varies by shift | N14: No | O14: No development conversations in the quarter | P14: =IF(A14="","",IF(COUNTA(D14)+COUNTA(F14)+COUNTA(H14)+COUNTA(J14)+COUNTA(L14)+COUNTA(N14)<6,"",IF(D14="Yes",1,IF(D14="Sometimes",0.5,0))+IF(F14="Yes",1,IF(F14="Sometimes",0.5,0))+IF(H14="Yes",1,IF(H14="Sometimes",0.5,0))+IF(J14="Yes",1,IF(J14="Sometimes",0.5,0))+IF(L14="Yes",1,IF(L14="Sometimes",0.5,0))+IF(N14="Yes",1,IF(N14="Sometimes",0.5,0)))) | Q14: =IF(P14="","",IF(D14="No",1,0)+IF(F14="No",1,0)+IF(H14="No",1,0)+IF(J14="No",1,0)+IF(L14="No",1,0)+IF(N14="No",1,0)) | R14: =IF(A14="","",6-COUNTA(E14)-COUNTA(G14)-COUNTA(I14)-COUNTA(K14)-COUNTA(M14)-COUNTA(O14)) | S14: =IF(P14="","",IF(OR(P14<3.5,Q14>=2),"Not yet",IF(AND(P14>=5,Q14=0),"Ready","Ready with support"))) | U14: =IF(A14="","",IF(T14<>"",T14,S14)) | X14: =IF(A14="","",IF(P14="","Score all six behaviors.",IF(R14>0,"Write the evidence. A blank evidence cell is a reputation score.",IF(U14="Ready","Scale now, and scale loudly.",IF(U14="Not yet","Hold at pilot scope until the gap closes. Name what closes it.",IF(V14="","Name a coach.",IF(W14="","Set a date.","Scale with support. Review on the date."))))))) | Y14: Team of 25 and no written standard. Contain at pilot scope; start with the standard.
P15: =IF(A15="","",IF(COUNTA(D15)+COUNTA(F15)+COUNTA(H15)+COUNTA(J15)+COUNTA(L15)+COUNTA(N15)<6,"",IF(D15="Yes",1,IF(D15="Sometimes",0.5,0))+IF(F15="Yes",1,IF(F15="Sometimes",0.5,0))+IF(H15="Yes",1,IF(H15="Sometimes",0.5,0))+IF(J15="Yes",1,IF(J15="Sometimes",0.5,0))+IF(L15="Yes",1,IF(L15="Sometimes",0.5,0))+IF(N15="Yes",1,IF(N15="Sometimes",0.5,0)))) | Q15: =IF(P15="","",IF(D15="No",1,0)+IF(F15="No",1,0)+IF(H15="No",1,0)+IF(J15="No",1,0)+IF(L15="No",1,0)+IF(N15="No",1,0)) | R15: =IF(A15="","",6-COUNTA(E15)-COUNTA(G15)-COUNTA(I15)-COUNTA(K15)-COUNTA(M15)-COUNTA(O15)) | S15: =IF(P15="","",IF(OR(P15<3.5,Q15>=2),"Not yet",IF(AND(P15>=5,Q15=0),"Ready","Ready with support"))) | U15: =IF(A15="","",IF(T15<>"",T15,S15)) | X15: =IF(A15="","",IF(P15="","Score all six behaviors.",IF(R15>0,"Write the evidence. A blank evidence cell is a reputation score.",IF(U15="Ready","Scale now, and scale loudly.",IF(U15="Not yet","Hold at pilot scope until the gap closes. Name what closes it.",IF(V15="","Name a coach.",IF(W15="","Set a date.","Scale with support. Review on the date.")))))))
P16: =IF(A16="","",IF(COUNTA(D16)+COUNTA(F16)+COUNTA(H16)+COUNTA(J16)+COUNTA(L16)+COUNTA(N16)<6,"",IF(D16="Yes",1,IF(D16="Sometimes",0.5,0))+IF(F16="Yes",1,IF(F16="Sometimes",0.5,0))+IF(H16="Yes",1,IF(H16="Sometimes",0.5,0))+IF(J16="Yes",1,IF(J16="Sometimes",0.5,0))+IF(L16="Yes",1,IF(L16="Sometimes",0.5,0))+IF(N16="Yes",1,IF(N16="Sometimes",0.5,0)))) | Q16: =IF(P16="","",IF(D16="No",1,0)+IF(F16="No",1,0)+IF(H16="No",1,0)+IF(J16="No",1,0)+IF(L16="No",1,0)+IF(N16="No",1,0)) | R16: =IF(A16="","",6-COUNTA(E16)-COUNTA(G16)-COUNTA(I16)-COUNTA(K16)-COUNTA(M16)-COUNTA(O16)) | S16: =IF(P16="","",IF(OR(P16<3.5,Q16>=2),"Not yet",IF(AND(P16>=5,Q16=0),"Ready","Ready with support"))) | U16: =IF(A16="","",IF(T16<>"",T16,S16)) | X16: =IF(A16="","",IF(P16="","Score all six behaviors.",IF(R16>0,"Write the evidence. A blank evidence cell is a reputation score.",IF(U16="Ready","Scale now, and scale loudly.",IF(U16="Not yet","Hold at pilot scope until the gap closes. Name what closes it.",IF(V16="","Name a coach.",IF(W16="","Set a date.","Scale with support. Review on the date.")))))))
P17: =IF(A17="","",IF(COUNTA(D17)+COUNTA(F17)+COUNTA(H17)+COUNTA(J17)+COUNTA(L17)+COUNTA(N17)<6,"",IF(D17="Yes",1,IF(D17="Sometimes",0.5,0))+IF(F17="Yes",1,IF(F17="Sometimes",0.5,0))+IF(H17="Yes",1,IF(H17="Sometimes",0.5,0))+IF(J17="Yes",1,IF(J17="Sometimes",0.5,0))+IF(L17="Yes",1,IF(L17="Sometimes",0.5,0))+IF(N17="Yes",1,IF(N17="Sometimes",0.5,0)))) | Q17: =IF(P17="","",IF(D17="No",1,0)+IF(F17="No",1,0)+IF(H17="No",1,0)+IF(J17="No",1,0)+IF(L17="No",1,0)+IF(N17="No",1,0)) | R17: =IF(A17="","",6-COUNTA(E17)-COUNTA(G17)-COUNTA(I17)-COUNTA(K17)-COUNTA(M17)-COUNTA(O17)) | S17: =IF(P17="","",IF(OR(P17<3.5,Q17>=2),"Not yet",IF(AND(P17>=5,Q17=0),"Ready","Ready with support"))) | U17: =IF(A17="","",IF(T17<>"",T17,S17)) | X17: =IF(A17="","",IF(P17="","Score all six behaviors.",IF(R17>0,"Write the evidence. A blank evidence cell is a reputation score.",IF(U17="Ready","Scale now, and scale loudly.",IF(U17="Not yet","Hold at pilot scope until the gap closes. Name what closes it.",IF(V17="","Name a coach.",IF(W17="","Set a date.","Scale with support. Review on the date.")))))))
P18: =IF(A18="","",IF(COUNTA(D18)+COUNTA(F18)+COUNTA(H18)+COUNTA(J18)+COUNTA(L18)+COUNTA(N18)<6,"",IF(D18="Yes",1,IF(D18="Sometimes",0.5,0))+IF(F18="Yes",1,IF(F18="Sometimes",0.5,0))+IF(H18="Yes",1,IF(H18="Sometimes",0.5,0))+IF(J18="Yes",1,IF(J18="Sometimes",0.5,0))+IF(L18="Yes",1,IF(L18="Sometimes",0.5,0))+IF(N18="Yes",1,IF(N18="Sometimes",0.5,0)))) | Q18: =IF(P18="","",IF(D18="No",1,0)+IF(F18="No",1,0)+IF(H18="No",1,0)+IF(J18="No",1,0)+IF(L18="No",1,0)+IF(N18="No",1,0)) | R18: =IF(A18="","",6-COUNTA(E18)-COUNTA(G18)-COUNTA(I18)-COUNTA(K18)-COUNTA(M18)-COUNTA(O18)) | S18: =IF(P18="","",IF(OR(P18<3.5,Q18>=2),"Not yet",IF(AND(P18>=5,Q18=0),"Ready","Ready with support"))) | U18: =IF(A18="","",IF(T18<>"",T18,S18)) | X18: =IF(A18="","",IF(P18="","Score all six behaviors.",IF(R18>0,"Write the evidence. A blank evidence cell is a reputation score.",IF(U18="Ready","Scale now, and scale loudly.",IF(U18="Not yet","Hold at pilot scope until the gap closes. Name what closes it.",IF(V18="","Name a coach.",IF(W18="","Set a date.","Scale with support. Review on the date.")))))))
P19: =IF(A19="","",IF(COUNTA(D19)+COUNTA(F19)+COUNTA(H19)+COUNTA(J19)+COUNTA(L19)+COUNTA(N19)<6,"",IF(D19="Yes",1,IF(D19="Sometimes",0.5,0))+IF(F19="Yes",1,IF(F19="Sometimes",0.5,0))+IF(H19="Yes",1,IF(H19="Sometimes",0.5,0))+IF(J19="Yes",1,IF(J19="Sometimes",0.5,0))+IF(L19="Yes",1,IF(L19="Sometimes",0.5,0))+IF(N19="Yes",1,IF(N19="Sometimes",0.5,0)))) | Q19: =IF(P19="","",IF(D19="No",1,0)+IF(F19="No",1,0)+IF(H19="No",1,0)+IF(J19="No",1,0)+IF(L19="No",1,0)+IF(N19="No",1,0)) | R19: =IF(A19="","",6-COUNTA(E19)-COUNTA(G19)-COUNTA(I19)-COUNTA(K19)-COUNTA(M19)-COUNTA(O19)) | S19: =IF(P19="","",IF(OR(P19<3.5,Q19>=2),"Not yet",IF(AND(P19>=5,Q19=0),"Ready","Ready with support"))) | U19: =IF(A19="","",IF(T19<>"",T19,S19)) | X19: =IF(A19="","",IF(P19="","Score all six behaviors.",IF(R19>0,"Write the evidence. A blank evidence cell is a reputation score.",IF(U19="Ready","Scale now, and scale loudly.",IF(U19="Not yet","Hold at pilot scope until the gap closes. Name what closes it.",IF(V19="","Name a coach.",IF(W19="","Set a date.","Scale with support. Review on the date.")))))))
P20: =IF(A20="","",IF(COUNTA(D20)+COUNTA(F20)+COUNTA(H20)+COUNTA(J20)+COUNTA(L20)+COUNTA(N20)<6,"",IF(D20="Yes",1,IF(D20="Sometimes",0.5,0))+IF(F20="Yes",1,IF(F20="Sometimes",0.5,0))+IF(H20="Yes",1,IF(H20="Sometimes",0.5,0))+IF(J20="Yes",1,IF(J20="Sometimes",0.5,0))+IF(L20="Yes",1,IF(L20="Sometimes",0.5,0))+IF(N20="Yes",1,IF(N20="Sometimes",0.5,0)))) | Q20: =IF(P20="","",IF(D20="No",1,0)+IF(F20="No",1,0)+IF(H20="No",1,0)+IF(J20="No",1,0)+IF(L20="No",1,0)+IF(N20="No",1,0)) | R20: =IF(A20="","",6-COUNTA(E20)-COUNTA(G20)-COUNTA(I20)-COUNTA(K20)-COUNTA(M20)-COUNTA(O20)) | S20: =IF(P20="","",IF(OR(P20<3.5,Q20>=2),"Not yet",IF(AND(P20>=5,Q20=0),"Ready","Ready with support"))) | U20: =IF(A20="","",IF(T20<>"",T20,S20)) | X20: =IF(A20="","",IF(P20="","Score all six behaviors.",IF(R20>0,"Write the evidence. A blank evidence cell is a reputation score.",IF(U20="Ready","Scale now, and scale loudly.",IF(U20="Not yet","Hold at pilot scope until the gap closes. Name what closes it.",IF(V20="","Name a coach.",IF(W20="","Set a date.","Scale with support. Review on the date.")))))))
P21: =IF(A21="","",IF(COUNTA(D21)+COUNTA(F21)+COUNTA(H21)+COUNTA(J21)+COUNTA(L21)+COUNTA(N21)<6,"",IF(D21="Yes",1,IF(D21="Sometimes",0.5,0))+IF(F21="Yes",1,IF(F21="Sometimes",0.5,0))+IF(H21="Yes",1,IF(H21="Sometimes",0.5,0))+IF(J21="Yes",1,IF(J21="Sometimes",0.5,0))+IF(L21="Yes",1,IF(L21="Sometimes",0.5,0))+IF(N21="Yes",1,IF(N21="Sometimes",0.5,0)))) | Q21: =IF(P21="","",IF(D21="No",1,0)+IF(F21="No",1,0)+IF(H21="No",1,0)+IF(J21="No",1,0)+IF(L21="No",1,0)+IF(N21="No",1,0)) | R21: =IF(A21="","",6-COUNTA(E21)-COUNTA(G21)-COUNTA(I21)-COUNTA(K21)-COUNTA(M21)-COUNTA(O21)) | S21: =IF(P21="","",IF(OR(P21<3.5,Q21>=2),"Not yet",IF(AND(P21>=5,Q21=0),"Ready","Ready with support"))) | U21: =IF(A21="","",IF(T21<>"",T21,S21)) | X21: =IF(A21="","",IF(P21="","Score all six behaviors.",IF(R21>0,"Write the evidence. A blank evidence cell is a reputation score.",IF(U21="Ready","Scale now, and scale loudly.",IF(U21="Not yet","Hold at pilot scope until the gap closes. Name what closes it.",IF(V21="","Name a coach.",IF(W21="","Set a date.","Scale with support. Review on the date.")))))))
P22: =IF(A22="","",IF(COUNTA(D22)+COUNTA(F22)+COUNTA(H22)+COUNTA(J22)+COUNTA(L22)+COUNTA(N22)<6,"",IF(D22="Yes",1,IF(D22="Sometimes",0.5,0))+IF(F22="Yes",1,IF(F22="Sometimes",0.5,0))+IF(H22="Yes",1,IF(H22="Sometimes",0.5,0))+IF(J22="Yes",1,IF(J22="Sometimes",0.5,0))+IF(L22="Yes",1,IF(L22="Sometimes",0.5,0))+IF(N22="Yes",1,IF(N22="Sometimes",0.5,0)))) | Q22: =IF(P22="","",IF(D22="No",1,0)+IF(F22="No",1,0)+IF(H22="No",1,0)+IF(J22="No",1,0)+IF(L22="No",1,0)+IF(N22="No",1,0)) | R22: =IF(A22="","",6-COUNTA(E22)-COUNTA(G22)-COUNTA(I22)-COUNTA(K22)-COUNTA(M22)-COUNTA(O22)) | S22: =IF(P22="","",IF(OR(P22<3.5,Q22>=2),"Not yet",IF(AND(P22>=5,Q22=0),"Ready","Ready with support"))) | U22: =IF(A22="","",IF(T22<>"",T22,S22)) | X22: =IF(A22="","",IF(P22="","Score all six behaviors.",IF(R22>0,"Write the evidence. A blank evidence cell is a reputation score.",IF(U22="Ready","Scale now, and scale loudly.",IF(U22="Not yet","Hold at pilot scope until the gap closes. Name what closes it.",IF(V22="","Name a coach.",IF(W22="","Set a date.","Scale with support. Review on the date.")))))))
P23: =IF(A23="","",IF(COUNTA(D23)+COUNTA(F23)+COUNTA(H23)+COUNTA(J23)+COUNTA(L23)+COUNTA(N23)<6,"",IF(D23="Yes",1,IF(D23="Sometimes",0.5,0))+IF(F23="Yes",1,IF(F23="Sometimes",0.5,0))+IF(H23="Yes",1,IF(H23="Sometimes",0.5,0))+IF(J23="Yes",1,IF(J23="Sometimes",0.5,0))+IF(L23="Yes",1,IF(L23="Sometimes",0.5,0))+IF(N23="Yes",1,IF(N23="Sometimes",0.5,0)))) | Q23: =IF(P23="","",IF(D23="No",1,0)+IF(F23="No",1,0)+IF(H23="No",1,0)+IF(J23="No",1,0)+IF(L23="No",1,0)+IF(N23="No",1,0)) | R23: =IF(A23="","",6-COUNTA(E23)-COUNTA(G23)-COUNTA(I23)-COUNTA(K23)-COUNTA(M23)-COUNTA(O23)) | S23: =IF(P23="","",IF(OR(P23<3.5,Q23>=2),"Not yet",IF(AND(P23>=5,Q23=0),"Ready","Ready with support"))) | U23: =IF(A23="","",IF(T23<>"",T23,S23)) | X23: =IF(A23="","",IF(P23="","Score all six behaviors.",IF(R23>0,"Write the evidence. A blank evidence cell is a reputation score.",IF(U23="Ready","Scale now, and scale loudly.",IF(U23="Not yet","Hold at pilot scope until the gap closes. Name what closes it.",IF(V23="","Name a coach.",IF(W23="","Set a date.","Scale with support. Review on the date.")))))))
P24: =IF(A24="","",IF(COUNTA(D24)+COUNTA(F24)+COUNTA(H24)+COUNTA(J24)+COUNTA(L24)+COUNTA(N24)<6,"",IF(D24="Yes",1,IF(D24="Sometimes",0.5,0))+IF(F24="Yes",1,IF(F24="Sometimes",0.5,0))+IF(H24="Yes",1,IF(H24="Sometimes",0.5,0))+IF(J24="Yes",1,IF(J24="Sometimes",0.5,0))+IF(L24="Yes",1,IF(L24="Sometimes",0.5,0))+IF(N24="Yes",1,IF(N24="Sometimes",0.5,0)))) | Q24: =IF(P24="","",IF(D24="No",1,0)+IF(F24="No",1,0)+IF(H24="No",1,0)+IF(J24="No",1,0)+IF(L24="No",1,0)+IF(N24="No",1,0)) | R24: =IF(A24="","",6-COUNTA(E24)-COUNTA(G24)-COUNTA(I24)-COUNTA(K24)-COUNTA(M24)-COUNTA(O24)) | S24: =IF(P24="","",IF(OR(P24<3.5,Q24>=2),"Not yet",IF(AND(P24>=5,Q24=0),"Ready","Ready with support"))) | U24: =IF(A24="","",IF(T24<>"",T24,S24)) | X24: =IF(A24="","",IF(P24="","Score all six behaviors.",IF(R24>0,"Write the evidence. A blank evidence cell is a reputation score.",IF(U24="Ready","Scale now, and scale loudly.",IF(U24="Not yet","Hold at pilot scope until the gap closes. Name what closes it.",IF(V24="","Name a coach.",IF(W24="","Set a date.","Scale with support. Review on the date.")))))))
P25: =IF(A25="","",IF(COUNTA(D25)+COUNTA(F25)+COUNTA(H25)+COUNTA(J25)+COUNTA(L25)+COUNTA(N25)<6,"",IF(D25="Yes",1,IF(D25="Sometimes",0.5,0))+IF(F25="Yes",1,IF(F25="Sometimes",0.5,0))+IF(H25="Yes",1,IF(H25="Sometimes",0.5,0))+IF(J25="Yes",1,IF(J25="Sometimes",0.5,0))+IF(L25="Yes",1,IF(L25="Sometimes",0.5,0))+IF(N25="Yes",1,IF(N25="Sometimes",0.5,0)))) | Q25: =IF(P25="","",IF(D25="No",1,0)+IF(F25="No",1,0)+IF(H25="No",1,0)+IF(J25="No",1,0)+IF(L25="No",1,0)+IF(N25="No",1,0)) | R25: =IF(A25="","",6-COUNTA(E25)-COUNTA(G25)-COUNTA(I25)-COUNTA(K25)-COUNTA(M25)-COUNTA(O25)) | S25: =IF(P25="","",IF(OR(P25<3.5,Q25>=2),"Not yet",IF(AND(P25>=5,Q25=0),"Ready","Ready with support"))) | U25: =IF(A25="","",IF(T25<>"",T25,S25)) | X25: =IF(A25="","",IF(P25="","Score all six behaviors.",IF(R25>0,"Write the evidence. A blank evidence cell is a reputation score.",IF(U25="Ready","Scale now, and scale loudly.",IF(U25="Not yet","Hold at pilot scope until the gap closes. Name what closes it.",IF(V25="","Name a coach.",IF(W25="","Set a date.","Scale with support. Review on the date.")))))))
P26: =IF(A26="","",IF(COUNTA(D26)+COUNTA(F26)+COUNTA(H26)+COUNTA(J26)+COUNTA(L26)+COUNTA(N26)<6,"",IF(D26="Yes",1,IF(D26="Sometimes",0.5,0))+IF(F26="Yes",1,IF(F26="Sometimes",0.5,0))+IF(H26="Yes",1,IF(H26="Sometimes",0.5,0))+IF(J26="Yes",1,IF(J26="Sometimes",0.5,0))+IF(L26="Yes",1,IF(L26="Sometimes",0.5,0))+IF(N26="Yes",1,IF(N26="Sometimes",0.5,0)))) | Q26: =IF(P26="","",IF(D26="No",1,0)+IF(F26="No",1,0)+IF(H26="No",1,0)+IF(J26="No",1,0)+IF(L26="No",1,0)+IF(N26="No",1,0)) | R26: =IF(A26="","",6-COUNTA(E26)-COUNTA(G26)-COUNTA(I26)-COUNTA(K26)-COUNTA(M26)-COUNTA(O26)) | S26: =IF(P26="","",IF(OR(P26<3.5,Q26>=2),"Not yet",IF(AND(P26>=5,Q26=0),"Ready","Ready with support"))) | U26: =IF(A26="","",IF(T26<>"",T26,S26)) | X26: =IF(A26="","",IF(P26="","Score all six behaviors.",IF(R26>0,"Write the evidence. A blank evidence cell is a reputation score.",IF(U26="Ready","Scale now, and scale loudly.",IF(U26="Not yet","Hold at pilot scope until the gap closes. Name what closes it.",IF(V26="","Name a coach.",IF(W26="","Set a date.","Scale with support. Review on the date.")))))))
... P44: =IF(A44="","",IF(COUNTA(D44)+COUNTA(F44)+COUNTA(H44)+COUNTA(J44)+COUNTA(L44)+COUNTA(N44)<6,"",IF(D44="Yes",1,IF(D44="Sometimes",0.5,0))+IF(F44="Yes",1,IF(F44="Sometimes",0.5,0))+IF(H44="Yes",1,IF(H44="Sometimes",0.5,0))+IF(J44="Yes",1,IF(J44="Sometimes",0.5,0))+IF(L44="Yes",1,IF(L44="Sometimes",0.5,0))+IF(N44="Yes",1,IF(N44="Sometimes",0.5,0)))) | Q44: =IF(P44="","",IF(D44="No",1,0)+IF(F44="No",1,0)+IF(H44="No",1,0)+IF(J44="No",1,0)+IF(L44="No",1,0)+IF(N44="No",1,0)) | R44: =IF(A44="","",6-COUNTA(E44)-COUNTA(G44)-COUNTA(I44)-COUNTA(K44)-COUNTA(M44)-COUNTA(O44)) | S44: =IF(P44="","",IF(OR(P44<3.5,Q44>=2),"Not yet",IF(AND(P44>=5,Q44=0),"Ready","Ready with support"))) | U44: =IF(A44="","",IF(T44<>"",T44,S44)) | X44: =IF(A44="","",IF(P44="","Score all six behaviors.",IF(R44>0,"Write the evidence. A blank evidence cell is a reputation score.",IF(U44="Ready","Scale now, and scale loudly.",IF(U44="Not yet","Hold at pilot scope until the gap closes. Name what closes it.",IF(V44="","Name a coach.",IF(W44="","Set a date.","Scale with support. Review on the date.")))))))

Sheet Rollout Decision
B1: Rollout Decision: Who Is Ready to Run It?
B2: HOW TO USE THIS TAB: Answer the two evidence gates in the yellow cells. Everything else calculates from the Review. Bring this page to the rollout meeting and put it next to the enthusiasm.
B3: © 2026 Elizabeth A. Corey. All rights reserved. GROWTH Execution Model™. onthegrow.ai
B5: THE TWO EVIDENCE GATES (answer before counting managers) | C5: Yes or No
B6: Has the knowledge this rollout touches passed the readiness test? (Toolbox No. 3) | C6: Yes
B7: Does every consequential rule it will run have a named owner? (Toolbox No. 7) | C7: Yes
B8: =IF(OR(C6="No",C7="No"),"Rollout not ready. If either gate is missing, the best manager in the building cannot hold it.",IF(AND(C6="Yes",C7="Yes"),"Both gates passed. Now the decision is about the people who will run it.","Answer both gates."))
B10: THE MANAGEMENT LAYER | C10: Managers | D10: People reached
B11: Reviewed | C11: =COUNTIF(Review!$A$5:$A$44,"?*") | D11: =SUMIF(Review!$A$5:$A$44,"?*",Review!$C$5:$C$44)
B12: Ready | C12: =COUNTIF(Review!$U$5:$U$44,"Ready") | D12: =SUMIF(Review!$U$5:$U$44,"Ready",Review!$C$5:$C$44)
B13: Ready with support | C13: =COUNTIF(Review!$U$5:$U$44,"Ready with support") | D13: =SUMIF(Review!$U$5:$U$44,"Ready with support",Review!$C$5:$C$44)
B14: Not yet | C14: =COUNTIF(Review!$U$5:$U$44,"Not yet") | D14: =SUMIF(Review!$U$5:$U$44,"Not yet",Review!$C$5:$C$44)
B15: Rows with evidence missing | C15: =COUNTIFS(Review!$A$5:$A$44,"?*",Review!$R$5:$R$44,">0")
B17: WHICH BEHAVIOR FAILS MOST | C17: No | D17: Sometimes | E17: Share not Yes
B18: Sets written standards | C18: =COUNTIF(Review!$D$5:$D$44,"No") | D18: =COUNTIF(Review!$D$5:$D$44,"Sometimes") | E18: =IF($C$11=0,0,(C18+D18)/$C$11)
B19: Catches confident errors | C19: =COUNTIF(Review!$F$5:$F$44,"No") | D19: =COUNTIF(Review!$F$5:$F$44,"Sometimes") | E19: =IF($C$11=0,0,(C19+D19)/$C$11)
B20: Overrides and can say why | C20: =COUNTIF(Review!$H$5:$H$44,"No") | D20: =COUNTIF(Review!$H$5:$H$44,"Sometimes") | E20: =IF($C$11=0,0,(C20+D20)/$C$11)
B21: Delivers feedback before it piles up | C21: =COUNTIF(Review!$J$5:$J$44,"No") | D21: =COUNTIF(Review!$J$5:$J$44,"Sometimes") | E21: =IF($C$11=0,0,(C21+D21)/$C$11)
B22: Runs a consistent conversation | C22: =COUNTIF(Review!$L$5:$L$44,"No") | D22: =COUNTIF(Review!$L$5:$L$44,"Sometimes") | E22: =IF($C$11=0,0,(C22+D22)/$C$11)
B23: Coaches and develops, people and agents both | C23: =COUNTIF(Review!$N$5:$N$44,"No") | D23: =COUNTIF(Review!$N$5:$N$44,"Sometimes") | E23: =IF($C$11=0,0,(C23+D23)/$C$11)
B24: =IFERROR("Rehearse first: "&INDEX(B18:B23,MATCH(MAX(E18:E23),E18:E23,0)),"")
B26: SCALES NOW. SAY IT LOUDLY. | C26: Team | D26: People reached
B27: {=IFERROR(INDEX(Review!$A$5:$A$44,SMALL(IF(Review!$U$5:$U$44="Ready",ROW(Review!$U$5:$U$44)-ROW(Review!$U$5)+1),1))&"","")} | C27: {=IFERROR(INDEX(Review!$B$5:$B$44,SMALL(IF(Review!$U$5:$U$44="Ready",ROW(Review!$U$5:$U$44)-ROW(Review!$U$5)+1),1))&"","")} | D27: {=IFERROR(INDEX(Review!$C$5:$C$44,SMALL(IF(Review!$U$5:$U$44="Ready",ROW(Review!$U$5:$U$44)-ROW(Review!$U$5)+1),1)),"")}
B28: {=IFERROR(INDEX(Review!$A$5:$A$44,SMALL(IF(Review!$U$5:$U$44="Ready",ROW(Review!$U$5:$U$44)-ROW(Review!$U$5)+1),2))&"","")} | C28: {=IFERROR(INDEX(Review!$B$5:$B$44,SMALL(IF(Review!$U$5:$U$44="Ready",ROW(Review!$U$5:$U$44)-ROW(Review!$U$5)+1),2))&"","")} | D28: {=IFERROR(INDEX(Review!$C$5:$C$44,SMALL(IF(Review!$U$5:$U$44="Ready",ROW(Review!$U$5:$U$44)-ROW(Review!$U$5)+1),2)),"")}
B29: {=IFERROR(INDEX(Review!$A$5:$A$44,SMALL(IF(Review!$U$5:$U$44="Ready",ROW(Review!$U$5:$U$44)-ROW(Review!$U$5)+1),3))&"","")} | C29: {=IFERROR(INDEX(Review!$B$5:$B$44,SMALL(IF(Review!$U$5:$U$44="Ready",ROW(Review!$U$5:$U$44)-ROW(Review!$U$5)+1),3))&"","")} | D29: {=IFERROR(INDEX(Review!$C$5:$C$44,SMALL(IF(Review!$U$5:$U$44="Ready",ROW(Review!$U$5:$U$44)-ROW(Review!$U$5)+1),3)),"")}
B30: {=IFERROR(INDEX(Review!$A$5:$A$44,SMALL(IF(Review!$U$5:$U$44="Ready",ROW(Review!$U$5:$U$44)-ROW(Review!$U$5)+1),4))&"","")} | C30: {=IFERROR(INDEX(Review!$B$5:$B$44,SMALL(IF(Review!$U$5:$U$44="Ready",ROW(Review!$U$5:$U$44)-ROW(Review!$U$5)+1),4))&"","")} | D30: {=IFERROR(INDEX(Review!$C$5:$C$44,SMALL(IF(Review!$U$5:$U$44="Ready",ROW(Review!$U$5:$U$44)-ROW(Review!$U$5)+1),4)),"")}
B31: {=IFERROR(INDEX(Review!$A$5:$A$44,SMALL(IF(Review!$U$5:$U$44="Ready",ROW(Review!$U$5:$U$44)-ROW(Review!$U$5)+1),5))&"","")} | C31: {=IFERROR(INDEX(Review!$B$5:$B$44,SMALL(IF(Review!$U$5:$U$44="Ready",ROW(Review!$U$5:$U$44)-ROW(Review!$U$5)+1),5))&"","")} | D31: {=IFERROR(INDEX(Review!$C$5:$C$44,SMALL(IF(Review!$U$5:$U$44="Ready",ROW(Review!$U$5:$U$44)-ROW(Review!$U$5)+1),5)),"")}
B32: {=IFERROR(INDEX(Review!$A$5:$A$44,SMALL(IF(Review!$U$5:$U$44="Ready",ROW(Review!$U$5:$U$44)-ROW(Review!$U$5)+1),6))&"","")} | C32: {=IFERROR(INDEX(Review!$B$5:$B$44,SMALL(IF(Review!$U$5:$U$44="Ready",ROW(Review!$U$5:$U$44)-ROW(Review!$U$5)+1),6))&"","")} | D32: {=IFERROR(INDEX(Review!$C$5:$C$44,SMALL(IF(Review!$U$5:$U$44="Ready",ROW(Review!$U$5:$U$44)-ROW(Review!$U$5)+1),6)),"")}
B34: SCALES WITH SUPPORT | C34: Coach | D34: Date | E34: Next action
B35: {=IFERROR(INDEX(Review!$A$5:$A$44,SMALL(IF(Review!$U$5:$U$44="Ready with support",ROW(Review!$U$5:$U$44)-ROW(Review!$U$5)+1),1))&"","")} | C35: {=IFERROR(INDEX(Review!$V$5:$V$44,SMALL(IF(Review!$U$5:$U$44="Ready with support",ROW(Review!$U$5:$U$44)-ROW(Review!$U$5)+1),1))&"","")} | D35: {=IFERROR(IF(INDEX(Review!$W$5:$W$44,SMALL(IF(Review!$U$5:$U$44="Ready with support",ROW(Review!$U$5:$U$44)-ROW(Review!$U$5)+1),1))="","",TEXT(INDEX(Review!$W$5:$W$44,SMALL(IF(Review!$U$5:$U$44="Ready with support",ROW(Review!$U$5:$U$44)-ROW(Review!$U$5)+1),1)),"mm/dd/yyyy")),"")} | E35: {=IFERROR(INDEX(Review!$X$5:$X$44,SMALL(IF(Review!$U$5:$U$44="Ready with support",ROW(Review!$U$5:$U$44)-ROW(Review!$U$5)+1),1))&"","")}
B36: {=IFERROR(INDEX(Review!$A$5:$A$44,SMALL(IF(Review!$U$5:$U$44="Ready with support",ROW(Review!$U$5:$U$44)-ROW(Review!$U$5)+1),2))&"","")} | C36: {=IFERROR(INDEX(Review!$V$5:$V$44,SMALL(IF(Review!$U$5:$U$44="Ready with support",ROW(Review!$U$5:$U$44)-ROW(Review!$U$5)+1),2))&"","")} | D36: {=IFERROR(IF(INDEX(Review!$W$5:$W$44,SMALL(IF(Review!$U$5:$U$44="Ready with support",ROW(Review!$U$5:$U$44)-ROW(Review!$U$5)+1),2))="","",TEXT(INDEX(Review!$W$5:$W$44,SMALL(IF(Review!$U$5:$U$44="Ready with support",ROW(Review!$U$5:$U$44)-ROW(Review!$U$5)+1),2)),"mm/dd/yyyy")),"")} | E36: {=IFERROR(INDEX(Review!$X$5:$X$44,SMALL(IF(Review!$U$5:$U$44="Ready with support",ROW(Review!$U$5:$U$44)-ROW(Review!$U$5)+1),2))&"","")}
B37: {=IFERROR(INDEX(Review!$A$5:$A$44,SMALL(IF(Review!$U$5:$U$44="Ready with support",ROW(Review!$U$5:$U$44)-ROW(Review!$U$5)+1),3))&"","")} | C37: {=IFERROR(INDEX(Review!$V$5:$V$44,SMALL(IF(Review!$U$5:$U$44="Ready with support",ROW(Review!$U$5:$U$44)-ROW(Review!$U$5)+1),3))&"","")} | D37: {=IFERROR(IF(INDEX(Review!$W$5:$W$44,SMALL(IF(Review!$U$5:$U$44="Ready with support",ROW(Review!$U$5:$U$44)-ROW(Review!$U$5)+1),3))="","",TEXT(INDEX(Review!$W$5:$W$44,SMALL(IF(Review!$U$5:$U$44="Ready with support",ROW(Review!$U$5:$U$44)-ROW(Review!$U$5)+1),3)),"mm/dd/yyyy")),"")} | E37: {=IFERROR(INDEX(Review!$X$5:$X$44,SMALL(IF(Review!$U$5:$U$44="Ready with support",ROW(Review!$U$5:$U$44)-ROW(Review!$U$5)+1),3))&"","")}
B38: {=IFERROR(INDEX(Review!$A$5:$A$44,SMALL(IF(Review!$U$5:$U$44="Ready with support",ROW(Review!$U$5:$U$44)-ROW(Review!$U$5)+1),4))&"","")} | C38: {=IFERROR(INDEX(Review!$V$5:$V$44,SMALL(IF(Review!$U$5:$U$44="Ready with support",ROW(Review!$U$5:$U$44)-ROW(Review!$U$5)+1),4))&"","")} | D38: {=IFERROR(IF(INDEX(Review!$W$5:$W$44,SMALL(IF(Review!$U$5:$U$44="Ready with support",ROW(Review!$U$5:$U$44)-ROW(Review!$U$5)+1),4))="","",TEXT(INDEX(Review!$W$5:$W$44,SMALL(IF(Review!$U$5:$U$44="Ready with support",ROW(Review!$U$5:$U$44)-ROW(Review!$U$5)+1),4)),"mm/dd/yyyy")),"")} | E38: {=IFERROR(INDEX(Review!$X$5:$X$44,SMALL(IF(Review!$U$5:$U$44="Ready with support",ROW(Review!$U$5:$U$44)-ROW(Review!$U$5)+1),4))&"","")}
B39: {=IFERROR(INDEX(Review!$A$5:$A$44,SMALL(IF(Review!$U$5:$U$44="Ready with support",ROW(Review!$U$5:$U$44)-ROW(Review!$U$5)+1),5))&"","")} | C39: {=IFERROR(INDEX(Review!$V$5:$V$44,SMALL(IF(Review!$U$5:$U$44="Ready with support",ROW(Review!$U$5:$U$44)-ROW(Review!$U$5)+1),5))&"","")} | D39: {=IFERROR(IF(INDEX(Review!$W$5:$W$44,SMALL(IF(Review!$U$5:$U$44="Ready with support",ROW(Review!$U$5:$U$44)-ROW(Review!$U$5)+1),5))="","",TEXT(INDEX(Review!$W$5:$W$44,SMALL(IF(Review!$U$5:$U$44="Ready with support",ROW(Review!$U$5:$U$44)-ROW(Review!$U$5)+1),5)),"mm/dd/yyyy")),"")} | E39: {=IFERROR(INDEX(Review!$X$5:$X$44,SMALL(IF(Review!$U$5:$U$44="Ready with support",ROW(Review!$U$5:$U$44)-ROW(Review!$U$5)+1),5))&"","")}
B40: {=IFERROR(INDEX(Review!$A$5:$A$44,SMALL(IF(Review!$U$5:$U$44="Ready with support",ROW(Review!$U$5:$U$44)-ROW(Review!$U$5)+1),6))&"","")} | C40: {=IFERROR(INDEX(Review!$V$5:$V$44,SMALL(IF(Review!$U$5:$U$44="Ready with support",ROW(Review!$U$5:$U$44)-ROW(Review!$U$5)+1),6))&"","")} | D40: {=IFERROR(IF(INDEX(Review!$W$5:$W$44,SMALL(IF(Review!$U$5:$U$44="Ready with support",ROW(Review!$U$5:$U$44)-ROW(Review!$U$5)+1),6))="","",TEXT(INDEX(Review!$W$5:$W$44,SMALL(IF(Review!$U$5:$U$44="Ready with support",ROW(Review!$U$5:$U$44)-ROW(Review!$U$5)+1),6)),"mm/dd/yyyy")),"")} | E40: {=IFERROR(INDEX(Review!$X$5:$X$44,SMALL(IF(Review!$U$5:$U$44="Ready with support",ROW(Review!$U$5:$U$44)-ROW(Review!$U$5)+1),6))&"","")}
B42: STAYS AT PILOT SCOPE UNTIL THE GAP CLOSES | C42: Team | D42: People reached | E42: Next action
B43: {=IFERROR(INDEX(Review!$A$5:$A$44,SMALL(IF(Review!$U$5:$U$44="Not yet",ROW(Review!$U$5:$U$44)-ROW(Review!$U$5)+1),1))&"","")} | C43: {=IFERROR(INDEX(Review!$B$5:$B$44,SMALL(IF(Review!$U$5:$U$44="Not yet",ROW(Review!$U$5:$U$44)-ROW(Review!$U$5)+1),1))&"","")} | D43: {=IFERROR(INDEX(Review!$C$5:$C$44,SMALL(IF(Review!$U$5:$U$44="Not yet",ROW(Review!$U$5:$U$44)-ROW(Review!$U$5)+1),1)),"")} | E43: {=IFERROR(INDEX(Review!$X$5:$X$44,SMALL(IF(Review!$U$5:$U$44="Not yet",ROW(Review!$U$5:$U$44)-ROW(Review!$U$5)+1),1))&"","")}
B44: {=IFERROR(INDEX(Review!$A$5:$A$44,SMALL(IF(Review!$U$5:$U$44="Not yet",ROW(Review!$U$5:$U$44)-ROW(Review!$U$5)+1),2))&"","")} | C44: {=IFERROR(INDEX(Review!$B$5:$B$44,SMALL(IF(Review!$U$5:$U$44="Not yet",ROW(Review!$U$5:$U$44)-ROW(Review!$U$5)+1),2))&"","")} | D44: {=IFERROR(INDEX(Review!$C$5:$C$44,SMALL(IF(Review!$U$5:$U$44="Not yet",ROW(Review!$U$5:$U$44)-ROW(Review!$U$5)+1),2)),"")} | E44: {=IFERROR(INDEX(Review!$X$5:$X$44,SMALL(IF(Review!$U$5:$U$44="Not yet",ROW(Review!$U$5:$U$44)-ROW(Review!$U$5)+1),2))&"","")}
B45: {=IFERROR(INDEX(Review!$A$5:$A$44,SMALL(IF(Review!$U$5:$U$44="Not yet",ROW(Review!$U$5:$U$44)-ROW(Review!$U$5)+1),3))&"","")} | C45: {=IFERROR(INDEX(Review!$B$5:$B$44,SMALL(IF(Review!$U$5:$U$44="Not yet",ROW(Review!$U$5:$U$44)-ROW(Review!$U$5)+1),3))&"","")} | D45: {=IFERROR(INDEX(Review!$C$5:$C$44,SMALL(IF(Review!$U$5:$U$44="Not yet",ROW(Review!$U$5:$U$44)-ROW(Review!$U$5)+1),3)),"")} | E45: {=IFERROR(INDEX(Review!$X$5:$X$44,SMALL(IF(Review!$U$5:$U$44="Not yet",ROW(Review!$U$5:$U$44)-ROW(Review!$U$5)+1),3))&"","")}
B46: {=IFERROR(INDEX(Review!$A$5:$A$44,SMALL(IF(Review!$U$5:$U$44="Not yet",ROW(Review!$U$5:$U$44)-ROW(Review!$U$5)+1),4))&"","")} | C46: {=IFERROR(INDEX(Review!$B$5:$B$44,SMALL(IF(Review!$U$5:$U$44="Not yet",ROW(Review!$U$5:$U$44)-ROW(Review!$U$5)+1),4))&"","")} | D46: {=IFERROR(INDEX(Review!$C$5:$C$44,SMALL(IF(Review!$U$5:$U$44="Not yet",ROW(Review!$U$5:$U$44)-ROW(Review!$U$5)+1),4)),"")} | E46: {=IFERROR(INDEX(Review!$X$5:$X$44,SMALL(IF(Review!$U$5:$U$44="Not yet",ROW(Review!$U$5:$U$44)-ROW(Review!$U$5)+1),4))&"","")}
...
